Workbook

Sheet ЕЖЕДНЕВНЫЙ УЧЕТ
A1: Дата: | B1: =TODAY() -> 46139 | G1: Итого рабочих в списке
A2: Организация | C2: ВелесстройМонтаж | G2: =SUBTOTAL(3,E:E)-1-L1 -> 13680 | H2: =G2=(СВОД!F27+СВОД!H27) -> TRUE
A5: № | B5: Регион | C5: Площадка | D5: Табельный номер | E5: ФИО | F5: Дата рождения | G5: Гражданство | H5: Серия | I5: Паспорт | J5: Фактическая должность | K5: Участок/Отдел | L5: ВИЗА | M5: Вид визы | N5: Регион | O5: Срок до | P5: Въезд в РФ/Прием на работу
A6: 1 | B6: Амурский | C6: Амурский ГПЗ АСН | D6: МВ-0006869 | E6: Дьячков Виталий Дмитриевич | F6: 35424 | G6: РОССИЯ | H6: 10 17 | I6: 529508 | J6: Ведущий геодезист | K6: АУП | P6: 45845 | Q6: =IFERROR(VLOOKUP(J6,Настройка!$C$4:$E$121,2,),"Ошибка") -> ITR
A7: 2 | B7: Амурский | C7: Амурский ГПЗ АСН | D7: МВ-0008215 | E7: Магонов Иван Андреевич | F7: 33434 | G7: РОССИЯ | H7: 10 11 | I7: 267593 | J7: Ведущий инженер ПТО | K7: АУП | P7: 45947 | Q7: =IFERROR(VLOOKUP(J7,Настройка!$C$4:$E$121,2,),"Ошибка") -> ITR
A8: 3 | B8: Амурский | C8: Амурский ГПЗ АСН | D8: МВ-0001964 | E8: Криворотов Вячеслав Сергеевич | F8: 37526 | G8: РОССИЯ | H8: 52 22 | I8: 163000 | J8: Ведущий инженер ПТО | K8: АУП | P8: 46050 | Q8: =IFERROR(VLOOKUP(J8,Настройка!$C$4:$E$121,2,),"Ошибка") -> ITR
A9: 4 | B9: Амурский | C9: Амурский ГПЗ АСН | D9: МВ-0006961 | E9: Волкова Наталья Геннадиевна | F9: 27207 | G9: РОССИЯ | H9: 60 19 | I9: 600319 | J9: Заместитель начальника склада | K9: ВП и НП | P9: 46055 | Q9: =IFERROR(VLOOKUP(J9,Настройка!$C$4:$E$121,2,),"Ошибка") -> ITR
A10: 5 | B10: Амурский | C10: Амурский ГПЗ АСН | D10: ВМ-0103313 | E10: Клешич Никола | F10: 33225 | G10: СЕРБИЯ | I10: 013482408 | J10: Руководитель объекта | K10: АУП | L10: Рабочая | M10: Многократная | N10: Москва | O10: 46984 | P10: 46063 | Q10: =IFERROR(VLOOKUP(J10,Настройка!$C$4:$E$121,2,),"Ошибка") -> ITR
A11: 6 | B11: Амурский | C11: Амурский ГПЗ АСН | D11: МВ-0006757 | E11: Бекетова Анастасия Геннадьевна | F11: 34468 | G11: РОССИЯ | H11: 40 14 | I11: 053265 | J11: Ведущий инженер ПТО | K11: АУП | P11: 46068 | Q11: =IFERROR(VLOOKUP(J11,Настройка!$C$4:$E$121,2,),"Ошибка") -> ITR
A12: 7 | B12: Амурский | C12: Амурский ГПЗ АСН | D12: ВМ-0108424 | E12: Дыбов Александр Валерьевич | F12: 32184 | G12: РОССИЯ | H12: 18 23 | I12: 991201 | J12: Ведущий инженер ПТО | K12: АУП | P12: 46010 | Q12: =IFERROR(VLOOKUP(J12,Настройка!$C$4:$E$121,2,),"Ошибка") -> ITR
A13: 8 | B13: Амурский | C13: Амурский ГПЗ АСН | D13: МВ-0006441 | E13: Фесенко Максим | F13: 32527 | G13: КАЗАХСТАН | H13: 83 | I13: 1032328 | J13: Кладовщик | K13: ВП и НП | P13: 46105 | Q13: =IFERROR(VLOOKUP(J13,Настройка!$C$4:$E$121,2,),"Ошибка") -> ITR
A14: 9 | B14: Амурский | C14: Амурский ГПЗ АСН | D14: МВ-0010005 | E14: Ашуров Женишбек Абдыкаппарович | F14: 31176 | G14: КИРГИЗИЯ | H14: ID | I14: 2914991 | J14: Антикоррозийщик | K14: Участок АКЗ | P14: 46105 | Q14: =IFERROR(VLOOKUP(J14,Настройка!$C$4:$E$121,2,),"Ошибка") -> R
A15: 10 | B15: Амурский | C15: Амурский ГПЗ АСН | D15: МВ-0010007 | E15: Базаркулов Акылбек Арзикулович | F15: 28809 | G15: КИРГИЗИЯ | H15: ID | I15: 2543422 | J15: Антикоррозийщик | K15: Участок АКЗ | P15: 46105 | Q15: =IFERROR(VLOOKUP(J15,Настройка!$C$4:$E$121,2,),"Ошибка") -> R
A16: 11 | B16: Амурский | C16: Амурский ГПЗ АСН | D16: МВ-0010008 | E16: Бакбур Уулу Бексултан | F16: 33638 | G16: КИРГИЗИЯ | H16: AC | I16: 2859254 | J16: Антикоррозийщик | K16: Участок АКЗ | P16: 46105 | Q16: =IFERROR(VLOOKUP(J16,Настройка!$C$4:$E$121,2,),"Ошибка") -> R
A17: 12 | B17: Амурский | C17: Амурский ГПЗ АСН | D17: МВ-0010009 | E17: Бакиев Адылбек Усупжанович | F17: 29641 | G17: КИРГИЗИЯ | H17: ID | I17: 3151461 | J17: Антикоррозийщик | K17: Участок АКЗ | P17: 46105 | Q17: =IFERROR(VLOOKUP(J17,Настройка!$C$4:$E$121,2,),"Ошибка") -> R
A18: 13 | B18: Амурский | C18: Амурский ГПЗ АСН | D18: МВ-0010011 | E18: Бакиев Расулжан Усупжанович | F18: 31496 | G18: КИРГИЗИЯ | H18: ID | I18: 0253742 | J18: Антикоррозийщик | K18: Участок АКЗ | P18: 46105 | Q18: =IFERROR(VLOOKUP(J18,Настройка!$C$4:$E$121,2,),"Ошибка") -> R
A19: 14 | B19: Амурский | C19: Амурский ГПЗ АСН | D19: МВ-0010012 | E19: Бакиев Рустамбек Усупжанович | F19: 30389 | G19: КИРГИЗИЯ | H19: ID | I19: 1047523 | J19: Антикоррозийщик | K19: Участок АКЗ | P19: 46105 | Q19: =IFERROR(VLOOKUP(J19,Настройка!$C$4:$E$121,2,),"Ошибка") -> R
A20: 15 | B20: Амурский | C20: Амурский ГПЗ АСН | D20: МВ-0010014 | E20: Борукулов Сталбек Бегалыевич | F20: 32159 | G20: КИРГИЗИЯ | H20: ID | I20: 2934482 | J20: Антикоррозийщик | K20: Участок АКЗ | P20: 46105 | Q20: =IFERROR(VLOOKUP(J20,Настройка!$C$4:$E$121,2,),"Ошибка") -> R
A21: 16 | B21: Амурский | C21: Амурский ГПЗ АСН | D21: МВ-0010016 | E21: Буамырзаев Хаятбек Уркунбаевич | F21: 31253 | G21: КИРГИЗИЯ | H21: ID | I21: 4297954 | J21: Антикоррозийщик | K21: Участок АКЗ | P21: 46105 | Q21: =IFERROR(VLOOKUP(J21,Настройка!$C$4:$E$121,2,),"Ошибка") -> R
A22: 17 | B22: Амурский | C22: Амурский ГПЗ АСН | D22: МВ-0010017 | E22: Далибоев Женишбек | F22: 33003 | G22: КИРГИЗИЯ | H22: AC | I22: 4407655 | J22: Антикоррозийщик | K22: Участок АКЗ | P22: 46105 | Q22: =IFERROR(VLOOKUP(J22,Настройка!$C$4:$E$121,2,),"Ошибка") -> R
... A40: 35 | B40: Амурский | C40: Амурский ГПЗ АСН | D40: МВ-0010091 | E40: Ыстамов Адилет Сиязович | F40: 38095 | G40: КИРГИЗИЯ | H40: PE | I40: 0376624 | J40: Антикоррозийщик | K40: Участок АКЗ | P40: 46106 | Q40: =IFERROR(VLOOKUP(J40,Настройка!$C$4:$E$121,2,),"Ошибка") -> R
A41: 36 | B41: Амурский | C41: Амурский ГПЗ АСН | D41: ВМ-0147851 | E41: Татимбаев Серик Байменович | F41: 29440 | G41: КАЗАХСТАН | I41: 026256539 | J41: Антикоррозийщик | K41: Участок АКЗ | P41: 46083 | Q41: =IFERROR(VLOOKUP(J41,Настройка!$C$4:$E$121,2,),"Ошибка") -> R
A42: 37 | B42: Амурский | C42: Амурский ГПЗ АСН | D42: МВ-0008726 | E42: Соловец Никита Андреевич | F42: 36861 | G42: РОССИЯ | H42: 08 20 | I42: 699621 | J42: Антикоррозийщик | K42: Участок АКЗ | P42: 46090 | Q42: =IFERROR(VLOOKUP(J42,Настройка!$C$4:$E$121,2,),"Ошибка") -> R
A43: 38 | B43: Амурский | C43: Амурский ГПЗ АСН | D43: ВМ-0169036 | E43: Бехера Самбит | F43: 37245 | G43: ИНДИЯ | H43: Y | I43: 7006291 | J43: Антикоррозийщик | K43: Участок АКЗ | L43: Рабочая | M43: Многократная | N43: Амур | O43: 46308 | P43: 46029 | Q43: =IFERROR(VLOOKUP(J43,Настройка!$C$4:$E$121,2,),"Ошибка") -> R
A44: 39 | B44: Амурский | C44: Амурский ГПЗ АСН | D44: ВМ-0079380 | E44: Рожков Константин | F44: 29855 | G44: КАЗАХСТАН | H44: N | I44: 13106846 | J44: Маляр | K44: Участок АКЗ | P44: 46062 | Q44: =IFERROR(VLOOKUP(J44,Настройка!$C$4:$E$121,2,),"Ошибка") -> R
A45: 40 | B45: Амурский | C45: Амурский ГПЗ АСН | D45: ВМ-0169030 | E45: Яррамсетти Бхаскарарао | F45: 36912 | G45: ИНДИЯ | H45: W | I45: 8100262 | J45: Антикоррозийщик | K45: Участок АКЗ | L45: Рабочая | M45: Многократная | N45: Амур | O45: 46308 | P45: 46060 | Q45: =IFERROR(VLOOKUP(J45,Настройка!$C$4:$E$121,2,),"Ошибка") -> R
A46: 41 | B46: Амурский | C46: Амурский ГПЗ АСН | D46: ВМ-0169087 | E46: Мутхяла Джохн | F46: 37119 | G46: ИНДИЯ | H46: Y | I46: 7698781 | J46: Антикоррозийщик | K46: Участок АКЗ | L46: Рабочая | M46: Многократная | N46: Амур | O46: 46308 | P46: 46060 | Q46: =IFERROR(VLOOKUP(J46,Настройка!$C$4:$E$121,2,),"Ошибка") -> R
A47: 42 | B47: Амурский | C47: Амурский ГПЗ АСН | D47: МВ-0008410 | E47: Абилкайрова Динара | F47: 30318 | G47: КАЗАХСТАН | H47: N | I47: 17750289 | J47: Маляр | K47: Участок АКЗ | P47: 46069 | Q47: =IFERROR(VLOOKUP(J47,Настройка!$C$4:$E$121,2,),"Ошибка") -> R
A48: 43 | B48: Амурский | C48: Амурский ГПЗ АСН | D48: МВ-0006107 | E48: Ахмад Серадж | F48: 33373 | G48: ИНДИЯ | H48: T | I48: 4259551 | J48: Антикоррозийщик | K48: Участок АКЗ | L48: Рабочая | M48: Многократная | N48: Амур | O48: 46385 | P48: 45993 | Q48: =IFERROR(VLOOKUP(J48,Настройка!$C$4:$E$121,2,),"Ошибка") -> R
A49: 44 | B49: Амурский | C49: Амурский ГПЗ АСН | D49: МВ-0008409 | E49: Исмайлова Лола Канатовна | F49: 38293 | G49: КАЗАХСТАН | I49: 047377605 | J49: Маляр | K49: Участок АКЗ | P49: 46069 | Q49: =IFERROR(VLOOKUP(J49,Настройка!$C$4:$E$121,2,),"Ошибка") -> R
A50: 45 | B50: Амурский | C50: Амурский ГПЗ АСН | D50: МВ-0008990 | E50: Адельметов Виталий Рамилевич | F50: 34907 | G50: РОССИЯ | H50: 80 15 | I50: 261285 | J50: Антикоррозийщик | K50: Участок АКЗ | P50: 46084 | Q50: =IFERROR(VLOOKUP(J50,Настройка!$C$4:$E$121,2,),"Ошибка") -> R
A51: 46 | B51: Амурский | C51: Амурский ГПЗ АСН | D51: МВ-0006861 | E51: Данияр Уулу Элдияр | F51: 34496 | G51: КИРГИЗИЯ | H51: PE | I51: 0060758 | J51: Антикоррозийщик | K51: Участок АКЗ | P51: 46088 | Q51: =IFERROR(VLOOKUP(J51,Настройка!$C$4:$E$121,2,),"Ошибка") -> R
A52: 47 | B52: Амурский | C52: Амурский ГПЗ АСН | D52: МВ-0006332 | E52: Винодкумар Винодкумар | F52: 36572 | G52: ИНДИЯ | H52: U | I52: 8857119 | J52: Антикоррозийщик | K52: Участок АКЗ | L52: Рабочая | M52: Многократная | N52: Амур | O52: 46385 | P52: 45997 | Q52: =IFERROR(VLOOKUP(J52,Настройка!$C$4:$E$121,2,),"Ошибка") -> R
A53: 48 | B53: Амурский | C53: Амурский ГПЗ АСН | D53: ВМ-0173320 | E53: Шьям Бахадур | F53: 37472 | G53: ИНДИЯ | H53: V | I53: 0355042 | J53: Антикоррозийщик | K53: Участок АКЗ | L53: Рабочая | M53: Многократная | N53: Амур | O53: 46385 | P53: 46079 | Q53: =IFERROR(VLOOKUP(J53,Настройка!$C$4:$E$121,2,),"Ошибка") -> R
A54: 49 | B54: Амурский | C54: Амурский ГПЗ АСН | D54: ВМ-0169090 | E54: Гоуда Бипина | F54: 35157 | G54: ИНДИЯ | H54: W | I54: 9343025 | J54: Антикоррозийщик | K54: Участок АКЗ | L54: Рабочая | M54: Многократная | N54: Амур | O54: 46308 | P54: 46079 | Q54: =IFERROR(VLOOKUP(J54,Настройка!$C$4:$E$121,2,),"Ошибка") -> R
A55: 50 | B55: Амурский | C55: Амурский ГПЗ АСН | D55: МВ-0009700 | E55: Сону Кумар | F55: 37290 | G55: ИНДИЯ | H55: Y | I55: 7633714 | J55: Антикоррозийщик | K55: Участок АКЗ | L55: Рабочая | M55: Однократная | N55: Амур | O55: 46167 | P55: 46079 | Q55: =IFERROR(VLOOKUP(J55,Настройка!$C$4:$E$121,2,),"Ошибка") -> R
A56: 51 | B56: Амурский | C56: Амурский ГПЗ АСН | D56: МВ-0008547 | E56: Осмоналиев Шермамат Шамшиевич | F56: 26282 | G56: КИРГИЗИЯ | H56: ID | I56: 3174703 | J56: Антикоррозийщик | K56: Участок АКЗ | P56: 46062 | Q56: =IFERROR(VLOOKUP(J56,Настройка!$C$4:$E$121,2,),"Ошибка") -> R
A57: 52 | B57: Амурский | C57: Амурский ГПЗ АСН | D57: МВ-0009830 | E57: Акматов Темирбек Абдирашидович | F57: 27596 | G57: КИРГИЗИЯ | H57: ID | I57: 4661272 | J57: Антикоррозийщик | K57: Участок АКЗ | P57: 46091 | Q57: =IFERROR(VLOOKUP(J57,Настройка!$C$4:$E$121,2,),"Ошибка") -> R
A58: 53 | B58: Амурский | C58: Амурский ГПЗ АСН | D58: МВ-0009906 | E58: Бейшембаев Бейкут Темирланович | F58: 39134 | G58: КИРГИЗИЯ | H58: ID | I58: 3528354 | J58: Антикоррозийщик | K58: Участок АКЗ | P58: 46092 | Q58: =IFERROR(VLOOKUP(J58,Настройка!$C$4:$E$121,2,),"Ошибка") -> R
A59: 54 | B59: Амурский | C59: Амурский ГПЗ АСН | D59: МВ-0009905 | E59: Касеев Байел Мирбекович | F59: 39443 | G59: КИРГИЗИЯ | H59: ID | I59: 4166198 | J59: Антикоррозийщик | K59: Участок АКЗ | P59: 46092 | Q59: =IFERROR(VLOOKUP(J59,Настройка!$C$4:$E$121,2,),"Ошибка") -> R
...

Sheet СВОД
A1: Наименование (должность, специальность, профессия) | B1: Итого | C1: % | E1: Гражданство | F1: ITR | G1: ITR % | H1: R | I1: R % | K1: ГР Объект № 1. Шесхарис ЗАУ | L1: ОП Мурманск ГР ЦСКМС | M1: ОП Тарко-Сале | N1: Амурский ГПЗ | O1: ОП Кингисепп-2.ЕвроХим | P1: РП Новороссийск ОП Грушовая 7 | Q1: Диксон | R1: Амурский ГПЗ АСН | S1: Норильск | T1: Арктик СПГ-2 Гыдан | U1: АСПГ-2 НОВАРТИК | V1: ОП Гыдан GWP5A | W1: ОП Усть-Луга СПГ | X1: ОП Дом охотника № 5 | Y1: ОП Криница_Криница МОЛ 2 | Z1: ОП Усть-Луга. ТСБиМОТ | AA1: ОП Геленджик Марина | AB1: КС-7 Сивакинская | AC1: ОП Геленджик Винный город | AD1: Мурманск AWP1 | AE1: Ямал СПГ Текнип. CWP3A. train 4 | AF1: ОП Усадьба Дивноморское | AG1: ОП Усть-Луга. ВЖГ 7000 | AH1: ОП Национальный центр РОССИЯ | AI1: ОП Региональный южный ВЖГ | AJ1: ОП Новый Уренгой/ГР Новый Уренгой | AK1: ОП Новый Уренгой/Новый Уренгой. ЦГБ Хирургический корпус | AL1: ОП Новый Уренгой/Кванториум | AM1: ОП Новый Уренгой/Офис Газпром добыча Уренгой | AN1: ОП Новый Уренгой/Променад | AO1: ОП Новый Уренгой/Культурный центр | AP1: ОП Большой Камень | AQ1: ОП Сочи-2 | AR1: АГХК. Полиэтилен | AS1: ОП Кутузовский СБер К32 | AT1: ОП Карелия.Садовый Дом № 1/Дом № 2 | AU1: ОП БЦ Багратион
A2: Руководитель проекта | B2: =COUNTIF('ЕЖЕДНЕВНЫЙ УЧЕТ'!J:J,СВОД!A2) -> 9 | C2: =IFERROR(B2/$B$121,"") -> 0.00065789474 | E2: АЗЕРБАЙДЖАН | F2: =COUNTIFS('ЕЖЕДНЕВНЫЙ УЧЕТ'!$G:$G,СВОД!$E2,'ЕЖЕДНЕВНЫЙ УЧЕТ'!$Q:$Q,СВОД!F$1) -> 0 | G2: =IFERROR(F2/$F$27,"") -> 0 | H2: =COUNTIFS('ЕЖЕДНЕВНЫЙ УЧЕТ'!$G:$G,СВОД!$E2,'ЕЖЕДНЕВНЫЙ УЧЕТ'!$Q:$Q,СВОД!H$1) -> 0 | I2: =IFERROR(H2/$H$27,"") -> 0 | K2: =COUNTIFS('ЕЖЕДНЕВНЫЙ УЧЕТ'!$J:$J,$A2,'ЕЖЕДНЕВНЫЙ УЧЕТ'!$C:$C,K$1) -> 0 | L2: =COUNTIFS('ЕЖЕДНЕВНЫЙ УЧЕТ'!$J:$J,$A2,'ЕЖЕДНЕВНЫЙ УЧЕТ'!$C:$C,L$1) -> 0 | M2: =COUNTIFS('ЕЖЕДНЕВНЫЙ УЧЕТ'!$J:$J,$A2,'ЕЖЕДНЕВНЫЙ УЧЕТ'!$C:$C,M$1) -> 0 | N2: =COUNTIFS('ЕЖЕДНЕВНЫЙ УЧЕТ'!$J:$J,$A2,'ЕЖЕДНЕВНЫЙ УЧЕТ'!$C:$C,N$1) -> 0 | O2: =COUNTIFS('ЕЖЕДНЕВНЫЙ УЧЕТ'!$J:$J,$A2,'ЕЖЕДНЕВНЫЙ УЧЕТ'!$C:$C,O$1) -> 1 | P2: =COUNTIFS('ЕЖЕДНЕВНЫЙ УЧЕТ'!$J:$J,$A2,'ЕЖЕДНЕВНЫЙ УЧЕТ'!$C:$C,P$1) -> 0 | Q2: =COUNTIFS('ЕЖЕДНЕВНЫЙ УЧЕТ'!$J:$J,$A2,'ЕЖЕДНЕВНЫЙ УЧЕТ'!$C:$C,Q$1) -> 0 | R2: =COUNTIFS('ЕЖЕДНЕВНЫЙ УЧЕТ'!$J:$J,$A2,'ЕЖЕДНЕВНЫЙ УЧЕТ'!$C:$C,R$1) -> 0 | ... AU2: =COUNTIFS('ЕЖЕДНЕВНЫЙ УЧЕТ'!$J:$J,$A2,'ЕЖЕДНЕВНЫЙ УЧЕТ'!$C:$C,AU$1) -> 0
A3: Заместитель руководителя проекта по строительству | B3: =COUNTIF('ЕЖЕДНЕВНЫЙ УЧЕТ'!J:J,СВОД!A3) -> 23 | C3: =IFERROR(B3/$B$121,"") -> 0.0016812865 | E3: АРМЕНИЯ | F3: =COUNTIFS('ЕЖЕДНЕВНЫЙ УЧЕТ'!$G:$G,СВОД!$E3,'ЕЖЕДНЕВНЫЙ УЧЕТ'!$Q:$Q,СВОД!F$1) -> 1 | G3: =IFERROR(F3/$F$27,"") -> 0.00047326077 | H3: =COUNTIFS('ЕЖЕДНЕВНЫЙ УЧЕТ'!$G:$G,СВОД!$E3,'ЕЖЕДНЕВНЫЙ УЧЕТ'!$Q:$Q,СВОД!H$1) -> 0 | I3: =IFERROR(H3/$H$27,"") -> 0 | K3: =COUNTIFS('ЕЖЕДНЕВНЫЙ УЧЕТ'!$J:$J,$A3,'ЕЖЕДНЕВНЫЙ УЧЕТ'!$C:$C,K$1) -> 0 | L3: =COUNTIFS('ЕЖЕДНЕВНЫЙ УЧЕТ'!$J:$J,$A3,'ЕЖЕДНЕВНЫЙ УЧЕТ'!$C:$C,L$1) -> 0 | M3: =COUNTIFS('ЕЖЕДНЕВНЫЙ УЧЕТ'!$J:$J,$A3,'ЕЖЕДНЕВНЫЙ УЧЕТ'!$C:$C,M$1) -> 0 | N3: =COUNTIFS('ЕЖЕДНЕВНЫЙ УЧЕТ'!$J:$J,$A3,'ЕЖЕДНЕВНЫЙ УЧЕТ'!$C:$C,N$1) -> 0 | O3: =COUNTIFS('ЕЖЕДНЕВНЫЙ УЧЕТ'!$J:$J,$A3,'ЕЖЕДНЕВНЫЙ УЧЕТ'!$C:$C,O$1) -> 3 | P3: =COUNTIFS('ЕЖЕДНЕВНЫЙ УЧЕТ'!$J:$J,$A3,'ЕЖЕДНЕВНЫЙ УЧЕТ'!$C:$C,P$1) -> 0 | Q3: =COUNTIFS('ЕЖЕДНЕВНЫЙ УЧЕТ'!$J:$J,$A3,'ЕЖЕДНЕВНЫЙ УЧЕТ'!$C:$C,Q$1) -> 0 | R3: =COUNTIFS('ЕЖЕДНЕВНЫЙ УЧЕТ'!$J:$J,$A3,'ЕЖЕДНЕВНЫЙ УЧЕТ'!$C:$C,R$1) -> 0 | ... AU3: =COUNTIFS('ЕЖЕДНЕВНЫЙ УЧЕТ'!$J:$J,$A3,'ЕЖЕДНЕВНЫЙ УЧЕТ'!$C:$C,AU$1) -> 0
A4: Главный инженер | B4: =COUNTIF('ЕЖЕДНЕВНЫЙ УЧЕТ'!J:J,СВОД!A4) -> 2 | C4: =IFERROR(B4/$B$121,"") -> 0.00014619883 | E4: БЕЛАРУСЬ | F4: =COUNTIFS('ЕЖЕДНЕВНЫЙ УЧЕТ'!$G:$G,СВОД!$E4,'ЕЖЕДНЕВНЫЙ УЧЕТ'!$Q:$Q,СВОД!F$1) -> 30 | G4: =IFERROR(F4/$F$27,"") -> 0.014197823 | H4: =COUNTIFS('ЕЖЕДНЕВНЫЙ УЧЕТ'!$G:$G,СВОД!$E4,'ЕЖЕДНЕВНЫЙ УЧЕТ'!$Q:$Q,СВОД!H$1) -> 52 | I4: =IFERROR(H4/$H$27,"") -> 0.0044955477 | K4: =COUNTIFS('ЕЖЕДНЕВНЫЙ УЧЕТ'!$J:$J,$A4,'ЕЖЕДНЕВНЫЙ УЧЕТ'!$C:$C,K$1) -> 0 | L4: =COUNTIFS('ЕЖЕДНЕВНЫЙ УЧЕТ'!$J:$J,$A4,'ЕЖЕДНЕВНЫЙ УЧЕТ'!$C:$C,L$1) -> 0 | M4: =COUNTIFS('ЕЖЕДНЕВНЫЙ УЧЕТ'!$J:$J,$A4,'ЕЖЕДНЕВНЫЙ УЧЕТ'!$C:$C,M$1) -> 0 | N4: =COUNTIFS('ЕЖЕДНЕВНЫЙ УЧЕТ'!$J:$J,$A4,'ЕЖЕДНЕВНЫЙ УЧЕТ'!$C:$C,N$1) -> 0 | O4: =COUNTIFS('ЕЖЕДНЕВНЫЙ УЧЕТ'!$J:$J,$A4,'ЕЖЕДНЕВНЫЙ УЧЕТ'!$C:$C,O$1) -> 0 | P4: =COUNTIFS('ЕЖЕДНЕВНЫЙ УЧЕТ'!$J:$J,$A4,'ЕЖЕДНЕВНЫЙ УЧЕТ'!$C:$C,P$1) -> 0 | Q4: =COUNTIFS('ЕЖЕДНЕВНЫЙ УЧЕТ'!$J:$J,$A4,'ЕЖЕДНЕВНЫЙ УЧЕТ'!$C:$C,Q$1) -> 0 | R4: =COUNTIFS('ЕЖЕДНЕВНЫЙ УЧЕТ'!$J:$J,$A4,'ЕЖЕДНЕВНЫЙ УЧЕТ'!$C:$C,R$1) -> 0 | ... AU4: =COUNTIFS('ЕЖЕДНЕВНЫЙ УЧЕТ'!$J:$J,$A4,'ЕЖЕДНЕВНЫЙ УЧЕТ'!$C:$C,AU$1) -> 0
A5: Заместитель руководителя проекта по общим вопросам | B5: =COUNTIF('ЕЖЕДНЕВНЫЙ УЧЕТ'!J:J,СВОД!A5) -> 3 | C5: =IFERROR(B5/$B$121,"") -> 0.00021929825 | E5: БОСНИЯ И ГЕРЦЕГОВИНА | F5: =COUNTIFS('ЕЖЕДНЕВНЫЙ УЧЕТ'!$G:$G,СВОД!$E5,'ЕЖЕДНЕВНЫЙ УЧЕТ'!$Q:$Q,СВОД!F$1) -> 17 | G5: =IFERROR(F5/$F$27,"") -> 0.008045433 | H5: =COUNTIFS('ЕЖЕДНЕВНЫЙ УЧЕТ'!$G:$G,СВОД!$E5,'ЕЖЕДНЕВНЫЙ УЧЕТ'!$Q:$Q,СВОД!H$1) -> 3 | I5: =IFERROR(H5/$H$27,"") -> 0.00025935852 | K5: =COUNTIFS('ЕЖЕДНЕВНЫЙ УЧЕТ'!$J:$J,$A5,'ЕЖЕДНЕВНЫЙ УЧЕТ'!$C:$C,K$1) -> 0 | L5: =COUNTIFS('ЕЖЕДНЕВНЫЙ УЧЕТ'!$J:$J,$A5,'ЕЖЕДНЕВНЫЙ УЧЕТ'!$C:$C,L$1) -> 0 | M5: =COUNTIFS('ЕЖЕДНЕВНЫЙ УЧЕТ'!$J:$J,$A5,'ЕЖЕДНЕВНЫЙ УЧЕТ'!$C:$C,M$1) -> 0 | N5: =COUNTIFS('ЕЖЕДНЕВНЫЙ УЧЕТ'!$J:$J,$A5,'ЕЖЕДНЕВНЫЙ УЧЕТ'!$C:$C,N$1) -> 0 | O5: =COUNTIFS('ЕЖЕДНЕВНЫЙ УЧЕТ'!$J:$J,$A5,'ЕЖЕДНЕВНЫЙ УЧЕТ'!$C:$C,O$1) -> 0 | P5: =COUNTIFS('ЕЖЕДНЕВНЫЙ УЧЕТ'!$J:$J,$A5,'ЕЖЕДНЕВНЫЙ УЧЕТ'!$C:$C,P$1) -> 0 | Q5: =COUNTIFS('ЕЖЕДНЕВНЫЙ УЧЕТ'!$J:$J,$A5,'ЕЖЕДНЕВНЫЙ УЧЕТ'!$C:$C,Q$1) -> 0 | R5: =COUNTIFS('ЕЖЕДНЕВНЫЙ УЧЕТ'!$J:$J,$A5,'ЕЖЕДНЕВНЫЙ УЧЕТ'!$C:$C,R$1) -> 0 | ... AU5: =COUNTIFS('ЕЖЕДНЕВНЫЙ УЧЕТ'!$J:$J,$A5,'ЕЖЕДНЕВНЫЙ УЧЕТ'!$C:$C,AU$1) -> 0
A6: Руководитель объекта | B6: =COUNTIF('ЕЖЕДНЕВНЫЙ УЧЕТ'!J:J,СВОД!A6) -> 12 | C6: =IFERROR(B6/$B$121,"") -> 0.00087719298 | E6: ГАНА | F6: =COUNTIFS('ЕЖЕДНЕВНЫЙ УЧЕТ'!$G:$G,СВОД!$E6,'ЕЖЕДНЕВНЫЙ УЧЕТ'!$Q:$Q,СВОД!F$1) -> 0 | G6: =IFERROR(F6/$F$27,"") -> 0 | H6: =COUNTIFS('ЕЖЕДНЕВНЫЙ УЧЕТ'!$G:$G,СВОД!$E6,'ЕЖЕДНЕВНЫЙ УЧЕТ'!$Q:$Q,СВОД!H$1) -> 0 | I6: =IFERROR(H6/$H$27,"") -> 0 | K6: =COUNTIFS('ЕЖЕДНЕВНЫЙ УЧЕТ'!$J:$J,$A6,'ЕЖЕДНЕВНЫЙ УЧЕТ'!$C:$C,K$1) -> 0 | L6: =COUNTIFS('ЕЖЕДНЕВНЫЙ УЧЕТ'!$J:$J,$A6,'ЕЖЕДНЕВНЫЙ УЧЕТ'!$C:$C,L$1) -> 0 | M6: =COUNTIFS('ЕЖЕДНЕВНЫЙ УЧЕТ'!$J:$J,$A6,'ЕЖЕДНЕВНЫЙ УЧЕТ'!$C:$C,M$1) -> 0 | N6: =COUNTIFS('ЕЖЕДНЕВНЫЙ УЧЕТ'!$J:$J,$A6,'ЕЖЕДНЕВНЫЙ УЧЕТ'!$C:$C,N$1) -> 0 | O6: =COUNTIFS('ЕЖЕДНЕВНЫЙ УЧЕТ'!$J:$J,$A6,'ЕЖЕДНЕВНЫЙ УЧЕТ'!$C:$C,O$1) -> 0 | P6: =COUNTIFS('ЕЖЕДНЕВНЫЙ УЧЕТ'!$J:$J,$A6,'ЕЖЕДНЕВНЫЙ УЧЕТ'!$C:$C,P$1) -> 0 | Q6: =COUNTIFS('ЕЖЕДНЕВНЫЙ УЧЕТ'!$J:$J,$A6,'ЕЖЕДНЕВНЫЙ УЧЕТ'!$C:$C,Q$1) -> 0 | R6: =COUNTIFS('ЕЖЕДНЕВНЫЙ УЧЕТ'!$J:$J,$A6,'ЕЖЕДНЕВНЫЙ УЧЕТ'!$C:$C,R$1) -> 1 | ... AU6: =COUNTIFS('ЕЖЕДНЕВНЫЙ УЧЕТ'!$J:$J,$A6,'ЕЖЕДНЕВНЫЙ УЧЕТ'!$C:$C,AU$1) -> 0
A7: Руководитель группы трудовой миграции | B7: =COUNTIF('ЕЖЕДНЕВНЫЙ УЧЕТ'!J:J,СВОД!A7) -> 5 | C7: =IFERROR(B7/$B$121,"") -> 0.00036549708 | E7: ИНДИЯ | F7: =COUNTIFS('ЕЖЕДНЕВНЫЙ УЧЕТ'!$G:$G,СВОД!$E7,'ЕЖЕДНЕВНЫЙ УЧЕТ'!$Q:$Q,СВОД!F$1) -> 105 | G7: =IFERROR(F7/$F$27,"") -> 0.049692381 | H7: =COUNTIFS('ЕЖЕДНЕВНЫЙ УЧЕТ'!$G:$G,СВОД!$E7,'ЕЖЕДНЕВНЫЙ УЧЕТ'!$Q:$Q,СВОД!H$1) -> 1781 | I7: =IFERROR(H7/$H$27,"") -> 0.15397251 | K7: =COUNTIFS('ЕЖЕДНЕВНЫЙ УЧЕТ'!$J:$J,$A7,'ЕЖЕДНЕВНЫЙ УЧЕТ'!$C:$C,K$1) -> 0 | L7: =COUNTIFS('ЕЖЕДНЕВНЫЙ УЧЕТ'!$J:$J,$A7,'ЕЖЕДНЕВНЫЙ УЧЕТ'!$C:$C,L$1) -> 1 | M7: =COUNTIFS('ЕЖЕДНЕВНЫЙ УЧЕТ'!$J:$J,$A7,'ЕЖЕДНЕВНЫЙ УЧЕТ'!$C:$C,M$1) -> 0 | N7: =COUNTIFS('ЕЖЕДНЕВНЫЙ УЧЕТ'!$J:$J,$A7,'ЕЖЕДНЕВНЫЙ УЧЕТ'!$C:$C,N$1) -> 0 | O7: =COUNTIFS('ЕЖЕДНЕВНЫЙ УЧЕТ'!$J:$J,$A7,'ЕЖЕДНЕВНЫЙ УЧЕТ'!$C:$C,O$1) -> 0 | P7: =COUNTIFS('ЕЖЕДНЕВНЫЙ УЧЕТ'!$J:$J,$A7,'ЕЖЕДНЕВНЫЙ УЧЕТ'!$C:$C,P$1) -> 0 | Q7: =COUNTIFS('ЕЖЕДНЕВНЫЙ УЧЕТ'!$J:$J,$A7,'ЕЖЕДНЕВНЫЙ УЧЕТ'!$C:$C,Q$1) -> 0 | R7: =COUNTIFS('ЕЖЕДНЕВНЫЙ УЧЕТ'!$J:$J,$A7,'ЕЖЕДНЕВНЫЙ УЧЕТ'!$C:$C,R$1) -> 0 | ... AU7: =COUNTIFS('ЕЖЕДНЕВНЫЙ УЧЕТ'!$J:$J,$A7,'ЕЖЕДНЕВНЫЙ УЧЕТ'!$C:$C,AU$1) -> 0
A8: Главный специалист группы трудовой миграции | B8: =COUNTIF('ЕЖЕДНЕВНЫЙ УЧЕТ'!J:J,СВОД!A8) -> 0 | C8: =IFERROR(B8/$B$121,"") -> 0 | E8: КАЗАХСТАН | F8: =COUNTIFS('ЕЖЕДНЕВНЫЙ УЧЕТ'!$G:$G,СВОД!$E8,'ЕЖЕДНЕВНЫЙ УЧЕТ'!$Q:$Q,СВОД!F$1) -> 256 | G8: =IFERROR(F8/$F$27,"") -> 0.12115476 | H8: =COUNTIFS('ЕЖЕДНЕВНЫЙ УЧЕТ'!$G:$G,СВОД!$E8,'ЕЖЕДНЕВНЫЙ УЧЕТ'!$Q:$Q,СВОД!H$1) -> 2384 | I8: =IFERROR(H8/$H$27,"") -> 0.20610357 | K8: =COUNTIFS('ЕЖЕДНЕВНЫЙ УЧЕТ'!$J:$J,$A8,'ЕЖЕДНЕВНЫЙ УЧЕТ'!$C:$C,K$1) -> 0 | L8: =COUNTIFS('ЕЖЕДНЕВНЫЙ УЧЕТ'!$J:$J,$A8,'ЕЖЕДНЕВНЫЙ УЧЕТ'!$C:$C,L$1) -> 0 | M8: =COUNTIFS('ЕЖЕДНЕВНЫЙ УЧЕТ'!$J:$J,$A8,'ЕЖЕДНЕВНЫЙ УЧЕТ'!$C:$C,M$1) -> 0 | N8: =COUNTIFS('ЕЖЕДНЕВНЫЙ УЧЕТ'!$J:$J,$A8,'ЕЖЕДНЕВНЫЙ УЧЕТ'!$C:$C,N$1) -> 0 | O8: =COUNTIFS('ЕЖЕДНЕВНЫЙ УЧЕТ'!$J:$J,$A8,'ЕЖЕДНЕВНЫЙ УЧЕТ'!$C:$C,O$1) -> 0 | P8: =COUNTIFS('ЕЖЕДНЕВНЫЙ УЧЕТ'!$J:$J,$A8,'ЕЖЕДНЕВНЫЙ УЧЕТ'!$C:$C,P$1) -> 0 | Q8: =COUNTIFS('ЕЖЕДНЕВНЫЙ УЧЕТ'!$J:$J,$A8,'ЕЖЕДНЕВНЫЙ УЧЕТ'!$C:$C,Q$1) -> 0 | R8: =COUNTIFS('ЕЖЕДНЕВНЫЙ УЧЕТ'!$J:$J,$A8,'ЕЖЕДНЕВНЫЙ УЧЕТ'!$C:$C,R$1) -> 0 | ... AU8: =COUNTIFS('ЕЖЕДНЕВНЫЙ УЧЕТ'!$J:$J,$A8,'ЕЖЕДНЕВНЫЙ УЧЕТ'!$C:$C,AU$1) -> 0
A9: Ведущий специалист группы трудовой миграции | B9: =COUNTIF('ЕЖЕДНЕВНЫЙ УЧЕТ'!J:J,СВОД!A9) -> 10 | C9: =IFERROR(B9/$B$121,"") -> 0.00073099415 | E9: КИРГИЗИЯ | F9: =COUNTIFS('ЕЖЕДНЕВНЫЙ УЧЕТ'!$G:$G,СВОД!$E9,'ЕЖЕДНЕВНЫЙ УЧЕТ'!$Q:$Q,СВОД!F$1) -> 144 | G9: =IFERROR(F9/$F$27,"") -> 0.06814955 | H9: =COUNTIFS('ЕЖЕДНЕВНЫЙ УЧЕТ'!$G:$G,СВОД!$E9,'ЕЖЕДНЕВНЫЙ УЧЕТ'!$Q:$Q,СВОД!H$1) -> 1803 | I9: =IFERROR(H9/$H$27,"") -> 0.15587447 | K9: =COUNTIFS('ЕЖЕДНЕВНЫЙ УЧЕТ'!$J:$J,$A9,'ЕЖЕДНЕВНЫЙ УЧЕТ'!$C:$C,K$1) -> 0 | L9: =COUNTIFS('ЕЖЕДНЕВНЫЙ УЧЕТ'!$J:$J,$A9,'ЕЖЕДНЕВНЫЙ УЧЕТ'!$C:$C,L$1) -> 0 | M9: =COUNTIFS('ЕЖЕДНЕВНЫЙ УЧЕТ'!$J:$J,$A9,'ЕЖЕДНЕВНЫЙ УЧЕТ'!$C:$C,M$1) -> 0 | N9: =COUNTIFS('ЕЖЕДНЕВНЫЙ УЧЕТ'!$J:$J,$A9,'ЕЖЕДНЕВНЫЙ УЧЕТ'!$C:$C,N$1) -> 0 | O9: =COUNTIFS('ЕЖЕДНЕВНЫЙ УЧЕТ'!$J:$J,$A9,'ЕЖЕДНЕВНЫЙ УЧЕТ'!$C:$C,O$1) -> 1 | P9: =COUNTIFS('ЕЖЕДНЕВНЫЙ УЧЕТ'!$J:$J,$A9,'ЕЖЕДНЕВНЫЙ УЧЕТ'!$C:$C,P$1) -> 0 | Q9: =COUNTIFS('ЕЖЕДНЕВНЫЙ УЧЕТ'!$J:$J,$A9,'ЕЖЕДНЕВНЫЙ УЧЕТ'!$C:$C,Q$1) -> 0 | R9: =COUNTIFS('ЕЖЕДНЕВНЫЙ УЧЕТ'!$J:$J,$A9,'ЕЖЕДНЕВНЫЙ УЧЕТ'!$C:$C,R$1) -> 0 | ... AU9: =COUNTIFS('ЕЖЕДНЕВНЫЙ УЧЕТ'!$J:$J,$A9,'ЕЖЕДНЕВНЫЙ УЧЕТ'!$C:$C,AU$1) -> 0
A10: Специалист группы трудовой миграции | B10: =COUNTIF('ЕЖЕДНЕВНЫЙ УЧЕТ'!J:J,СВОД!A10) -> 55 | C10: =IFERROR(B10/$B$121,"") -> 0.0040204678 | E10: КИТАЙ | F10: =COUNTIFS('ЕЖЕДНЕВНЫЙ УЧЕТ'!$G:$G,СВОД!$E10,'ЕЖЕДНЕВНЫЙ УЧЕТ'!$Q:$Q,СВОД!F$1) -> 9 | G10: =IFERROR(F10/$F$27,"") -> 0.0042593469 | H10: =COUNTIFS('ЕЖЕДНЕВНЫЙ УЧЕТ'!$G:$G,СВОД!$E10,'ЕЖЕДНЕВНЫЙ УЧЕТ'!$Q:$Q,СВОД!H$1) -> 72 | I10: =IFERROR(H10/$H$27,"") -> 0.0062246045 | K10: =COUNTIFS('ЕЖЕДНЕВНЫЙ УЧЕТ'!$J:$J,$A10,'ЕЖЕДНЕВНЫЙ УЧЕТ'!$C:$C,K$1) -> 0 | L10: =COUNTIFS('ЕЖЕДНЕВНЫЙ УЧЕТ'!$J:$J,$A10,'ЕЖЕДНЕВНЫЙ УЧЕТ'!$C:$C,L$1) -> 0 | M10: =COUNTIFS('ЕЖЕДНЕВНЫЙ УЧЕТ'!$J:$J,$A10,'ЕЖЕДНЕВНЫЙ УЧЕТ'!$C:$C,M$1) -> 1 | N10: =COUNTIFS('ЕЖЕДНЕВНЫЙ УЧЕТ'!$J:$J,$A10,'ЕЖЕДНЕВНЫЙ УЧЕТ'!$C:$C,N$1) -> 0 | O10: =COUNTIFS('ЕЖЕДНЕВНЫЙ УЧЕТ'!$J:$J,$A10,'ЕЖЕДНЕВНЫЙ УЧЕТ'!$C:$C,O$1) -> 9 | P10: =COUNTIFS('ЕЖЕДНЕВНЫЙ УЧЕТ'!$J:$J,$A10,'ЕЖЕДНЕВНЫЙ УЧЕТ'!$C:$C,P$1) -> 0 | Q10: =COUNTIFS('ЕЖЕДНЕВНЫЙ УЧЕТ'!$J:$J,$A10,'ЕЖЕДНЕВНЫЙ УЧЕТ'!$C:$C,Q$1) -> 0 | R10: =COUNTIFS('ЕЖЕДНЕВНЫЙ УЧЕТ'!$J:$J,$A10,'ЕЖЕДНЕВНЫЙ УЧЕТ'!$C:$C,R$1) -> 0 | ... AU10: =COUNTIFS('ЕЖЕДНЕВНЫЙ УЧЕТ'!$J:$J,$A10,'ЕЖЕДНЕВНЫЙ УЧЕТ'!$C:$C,AU$1) -> 1
A11: Руководитель группы кадрового документооборота | B11: =COUNTIF('ЕЖЕДНЕВНЫЙ УЧЕТ'!J:J,СВОД!A11) -> 4 | C11: =IFERROR(B11/$B$121,"") -> 0.00029239766 | E11: МОЛДОВА, РЕСПУБЛИКА | F11: =COUNTIFS('ЕЖЕДНЕВНЫЙ УЧЕТ'!$G:$G,СВОД!$E11,'ЕЖЕДНЕВНЫЙ УЧЕТ'!$Q:$Q,СВОД!F$1) -> 0 | G11: =IFERROR(F11/$F$27,"") -> 0 | H11: =COUNTIFS('ЕЖЕДНЕВНЫЙ УЧЕТ'!$G:$G,СВОД!$E11,'ЕЖЕДНЕВНЫЙ УЧЕТ'!$Q:$Q,СВОД!H$1) -> 0 | I11: =IFERROR(H11/$H$27,"") -> 0 | K11: =COUNTIFS('ЕЖЕДНЕВНЫЙ УЧЕТ'!$J:$J,$A11,'ЕЖЕДНЕВНЫЙ УЧЕТ'!$C:$C,K$1) -> 0 | L11: =COUNTIFS('ЕЖЕДНЕВНЫЙ УЧЕТ'!$J:$J,$A11,'ЕЖЕДНЕВНЫЙ УЧЕТ'!$C:$C,L$1) -> 0 | M11: =COUNTIFS('ЕЖЕДНЕВНЫЙ УЧЕТ'!$J:$J,$A11,'ЕЖЕДНЕВНЫЙ УЧЕТ'!$C:$C,M$1) -> 0 | N11: =COUNTIFS('ЕЖЕДНЕВНЫЙ УЧЕТ'!$J:$J,$A11,'ЕЖЕДНЕВНЫЙ УЧЕТ'!$C:$C,N$1) -> 0 | O11: =COUNTIFS('ЕЖЕДНЕВНЫЙ УЧЕТ'!$J:$J,$A11,'ЕЖЕДНЕВНЫЙ УЧЕТ'!$C:$C,O$1) -> 0 | P11: =COUNTIFS('ЕЖЕДНЕВНЫЙ УЧЕТ'!$J:$J,$A11,'ЕЖЕДНЕВНЫЙ УЧЕТ'!$C:$C,P$1) -> 0 | Q11: =COUNTIFS('ЕЖЕДНЕВНЫЙ УЧЕТ'!$J:$J,$A11,'ЕЖЕДНЕВНЫЙ УЧЕТ'!$C:$C,Q$1) -> 1 | R11: =COUNTIFS('ЕЖЕДНЕВНЫЙ УЧЕТ'!$J:$J,$A11,'ЕЖЕДНЕВНЫЙ УЧЕТ'!$C:$C,R$1) -> 0 | ... AU11: =COUNTIFS('ЕЖЕДНЕВНЫЙ УЧЕТ'!$J:$J,$A11,'ЕЖЕДНЕВНЫЙ УЧЕТ'!$C:$C,AU$1) -> 0
A12: Главный специалист по кадрам | B12: =COUNTIF('ЕЖЕДНЕВНЫЙ УЧЕТ'!J:J,СВОД!A12) -> 0 | C12: =IFERROR(B12/$B$121,"") -> 0 | E12: ПАКИСТАН | F12: =COUNTIFS('ЕЖЕДНЕВНЫЙ УЧЕТ'!$G:$G,СВОД!$E12,'ЕЖЕДНЕВНЫЙ УЧЕТ'!$Q:$Q,СВОД!F$1) -> 1 | G12: =IFERROR(F12/$F$27,"") -> 0.00047326077 | H12: =COUNTIFS('ЕЖЕДНЕВНЫЙ УЧЕТ'!$G:$G,СВОД!$E12,'ЕЖЕДНЕВНЫЙ УЧЕТ'!$Q:$Q,СВОД!H$1) -> 0 | I12: =IFERROR(H12/$H$27,"") -> 0 | K12: =COUNTIFS('ЕЖЕДНЕВНЫЙ УЧЕТ'!$J:$J,$A12,'ЕЖЕДНЕВНЫЙ УЧЕТ'!$C:$C,K$1) -> 0 | L12: =COUNTIFS('ЕЖЕДНЕВНЫЙ УЧЕТ'!$J:$J,$A12,'ЕЖЕДНЕВНЫЙ УЧЕТ'!$C:$C,L$1) -> 0 | M12: =COUNTIFS('ЕЖЕДНЕВНЫЙ УЧЕТ'!$J:$J,$A12,'ЕЖЕДНЕВНЫЙ УЧЕТ'!$C:$C,M$1) -> 0 | N12: =COUNTIFS('ЕЖЕДНЕВНЫЙ УЧЕТ'!$J:$J,$A12,'ЕЖЕДНЕВНЫЙ УЧЕТ'!$C:$C,N$1) -> 0 | O12: =COUNTIFS('ЕЖЕДНЕВНЫЙ УЧЕТ'!$J:$J,$A12,'ЕЖЕДНЕВНЫЙ УЧЕТ'!$C:$C,O$1) -> 0 | P12: =COUNTIFS('ЕЖЕДНЕВНЫЙ УЧЕТ'!$J:$J,$A12,'ЕЖЕДНЕВНЫЙ УЧЕТ'!$C:$C,P$1) -> 0 | Q12: =COUNTIFS('ЕЖЕДНЕВНЫЙ УЧЕТ'!$J:$J,$A12,'ЕЖЕДНЕВНЫЙ УЧЕТ'!$C:$C,Q$1) -> 0 | R12: =COUNTIFS('ЕЖЕДНЕВНЫЙ УЧЕТ'!$J:$J,$A12,'ЕЖЕДНЕВНЫЙ УЧЕТ'!$C:$C,R$1) -> 0 | ... AU12: =COUNTIFS('ЕЖЕДНЕВНЫЙ УЧЕТ'!$J:$J,$A12,'ЕЖЕДНЕВНЫЙ УЧЕТ'!$C:$C,AU$1) -> 0
A13: Ведущий специалист по кадрам | B13: =COUNTIF('ЕЖЕДНЕВНЫЙ УЧЕТ'!J:J,СВОД!A13) -> 9 | C13: =IFERROR(B13/$B$121,"") -> 0.00065789474 | E13: РОССИЯ | F13: =COUNTIFS('ЕЖЕДНЕВНЫЙ УЧЕТ'!$G:$G,СВОД!$E13,'ЕЖЕДНЕВНЫЙ УЧЕТ'!$Q:$Q,СВОД!F$1) -> 1116 | G13: =IFERROR(F13/$F$27,"") -> 0.52815902 | H13: =COUNTIFS('ЕЖЕДНЕВНЫЙ УЧЕТ'!$G:$G,СВОД!$E13,'ЕЖЕДНЕВНЫЙ УЧЕТ'!$Q:$Q,СВОД!H$1) -> 531 | I13: =IFERROR(H13/$H$27,"") -> 0.045906458 | K13: =COUNTIFS('ЕЖЕДНЕВНЫЙ УЧЕТ'!$J:$J,$A13,'ЕЖЕДНЕВНЫЙ УЧЕТ'!$C:$C,K$1) -> 0 | L13: =COUNTIFS('ЕЖЕДНЕВНЫЙ УЧЕТ'!$J:$J,$A13,'ЕЖЕДНЕВНЫЙ УЧЕТ'!$C:$C,L$1) -> 0 | M13: =COUNTIFS('ЕЖЕДНЕВНЫЙ УЧЕТ'!$J:$J,$A13,'ЕЖЕДНЕВНЫЙ УЧЕТ'!$C:$C,M$1) -> 1 | N13: =COUNTIFS('ЕЖЕДНЕВНЫЙ УЧЕТ'!$J:$J,$A13,'ЕЖЕДНЕВНЫЙ УЧЕТ'!$C:$C,N$1) -> 0 | O13: =COUNTIFS('ЕЖЕДНЕВНЫЙ УЧЕТ'!$J:$J,$A13,'ЕЖЕДНЕВНЫЙ УЧЕТ'!$C:$C,O$1) -> 1 | P13: =COUNTIFS('ЕЖЕДНЕВНЫЙ УЧЕТ'!$J:$J,$A13,'ЕЖЕДНЕВНЫЙ УЧЕТ'!$C:$C,P$1) -> 0 | Q13: =COUNTIFS('ЕЖЕДНЕВНЫЙ УЧЕТ'!$J:$J,$A13,'ЕЖЕДНЕВНЫЙ УЧЕТ'!$C:$C,Q$1) -> 0 | R13: =COUNTIFS('ЕЖЕДНЕВНЫЙ УЧЕТ'!$J:$J,$A13,'ЕЖЕДНЕВНЫЙ УЧЕТ'!$C:$C,R$1) -> 0 | ... AU13: =COUNTIFS('ЕЖЕДНЕВНЫЙ УЧЕТ'!$J:$J,$A13,'ЕЖЕДНЕВНЫЙ УЧЕТ'!$C:$C,AU$1) -> 0
A14: Специалист по кадрам | B14: =COUNTIF('ЕЖЕДНЕВНЫЙ УЧЕТ'!J:J,СВОД!A14) -> 35 | C14: =IFERROR(B14/$B$121,"") -> 0.0025584795 | E14: СЕВЕРНАЯ КОРЕЯ | F14: =COUNTIFS('ЕЖЕДНЕВНЫЙ УЧЕТ'!$G:$G,СВОД!$E14,'ЕЖЕДНЕВНЫЙ УЧЕТ'!$Q:$Q,СВОД!F$1) -> 0 | G14: =IFERROR(F14/$F$27,"") -> 0 | H14: =COUNTIFS('ЕЖЕДНЕВНЫЙ УЧЕТ'!$G:$G,СВОД!$E14,'ЕЖЕДНЕВНЫЙ УЧЕТ'!$Q:$Q,СВОД!H$1) -> 0 | I14: =IFERROR(H14/$H$27,"") -> 0 | K14: =COUNTIFS('ЕЖЕДНЕВНЫЙ УЧЕТ'!$J:$J,$A14,'ЕЖЕДНЕВНЫЙ УЧЕТ'!$C:$C,K$1) -> 0 | L14: =COUNTIFS('ЕЖЕДНЕВНЫЙ УЧЕТ'!$J:$J,$A14,'ЕЖЕДНЕВНЫЙ УЧЕТ'!$C:$C,L$1) -> 0 | M14: =COUNTIFS('ЕЖЕДНЕВНЫЙ УЧЕТ'!$J:$J,$A14,'ЕЖЕДНЕВНЫЙ УЧЕТ'!$C:$C,M$1) -> 0 | N14: =COUNTIFS('ЕЖЕДНЕВНЫЙ УЧЕТ'!$J:$J,$A14,'ЕЖЕДНЕВНЫЙ УЧЕТ'!$C:$C,N$1) -> 0 | O14: =COUNTIFS('ЕЖЕДНЕВНЫЙ УЧЕТ'!$J:$J,$A14,'ЕЖЕДНЕВНЫЙ УЧЕТ'!$C:$C,O$1) -> 7 | P14: =COUNTIFS('ЕЖЕДНЕВНЫЙ УЧЕТ'!$J:$J,$A14,'ЕЖЕДНЕВНЫЙ УЧЕТ'!$C:$C,P$1) -> 0 | Q14: =COUNTIFS('ЕЖЕДНЕВНЫЙ УЧЕТ'!$J:$J,$A14,'ЕЖЕДНЕВНЫЙ УЧЕТ'!$C:$C,Q$1) -> 0 | R14: =COUNTIFS('ЕЖЕДНЕВНЫЙ УЧЕТ'!$J:$J,$A14,'ЕЖЕДНЕВНЫЙ УЧЕТ'!$C:$C,R$1) -> 0 | ... AU14: =COUNTIFS('ЕЖЕДНЕВНЫЙ УЧЕТ'!$J:$J,$A14,'ЕЖЕДНЕВНЫЙ УЧЕТ'!$C:$C,AU$1) -> 0
A15: Ведущий специалист группы по подбору и адаптации | B15: =COUNTIF('ЕЖЕДНЕВНЫЙ УЧЕТ'!J:J,СВОД!A15) -> 6 | C15: =IFERROR(B15/$B$121,"") -> 0.00043859649 | E15: СЕВЕРНАЯ МАКЕДОНИЯ | F15: =COUNTIFS('ЕЖЕДНЕВНЫЙ УЧЕТ'!$G:$G,СВОД!$E15,'ЕЖЕДНЕВНЫЙ УЧЕТ'!$Q:$Q,СВОД!F$1) -> 1 | G15: =IFERROR(F15/$F$27,"") -> 0.00047326077 | H15: =COUNTIFS('ЕЖЕДНЕВНЫЙ УЧЕТ'!$G:$G,СВОД!$E15,'ЕЖЕДНЕВНЫЙ УЧЕТ'!$Q:$Q,СВОД!H$1) -> 1 | I15: =IFERROR(H15/$H$27,"") -> 8.645284e-05 | K15: =COUNTIFS('ЕЖЕДНЕВНЫЙ УЧЕТ'!$J:$J,$A15,'ЕЖЕДНЕВНЫЙ УЧЕТ'!$C:$C,K$1) -> 0 | L15: =COUNTIFS('ЕЖЕДНЕВНЫЙ УЧЕТ'!$J:$J,$A15,'ЕЖЕДНЕВНЫЙ УЧЕТ'!$C:$C,L$1) -> 0 | M15: =COUNTIFS('ЕЖЕДНЕВНЫЙ УЧЕТ'!$J:$J,$A15,'ЕЖЕДНЕВНЫЙ УЧЕТ'!$C:$C,M$1) -> 0 | N15: =COUNTIFS('ЕЖЕДНЕВНЫЙ УЧЕТ'!$J:$J,$A15,'ЕЖЕДНЕВНЫЙ УЧЕТ'!$C:$C,N$1) -> 0 | O15: =COUNTIFS('ЕЖЕДНЕВНЫЙ УЧЕТ'!$J:$J,$A15,'ЕЖЕДНЕВНЫЙ УЧЕТ'!$C:$C,O$1) -> 0 | P15: =COUNTIFS('ЕЖЕДНЕВНЫЙ УЧЕТ'!$J:$J,$A15,'ЕЖЕДНЕВНЫЙ УЧЕТ'!$C:$C,P$1) -> 0 | Q15: =COUNTIFS('ЕЖЕДНЕВНЫЙ УЧЕТ'!$J:$J,$A15,'ЕЖЕДНЕВНЫЙ УЧЕТ'!$C:$C,Q$1) -> 0 | R15: =COUNTIFS('ЕЖЕДНЕВНЫЙ УЧЕТ'!$J:$J,$A15,'ЕЖЕДНЕВНЫЙ УЧЕТ'!$C:$C,R$1) -> 0 | ... AI15: =COUNTIFS('ЕЖЕДНЕВНЫЙ УЧЕТ'!$J:$J,$A15,'ЕЖЕДНЕВНЫЙ УЧЕТ'!$C:$C,AI$1) -> 0 | AK15: =COUNTIFS('ЕЖЕДНЕВНЫЙ УЧЕТ'!$J:$J,$A15,'ЕЖЕДНЕВНЫЙ УЧЕТ'!$C:$C,AK$1) -> 0 | AL15: =COUNTIFS('ЕЖЕДНЕВНЫЙ УЧЕТ'!$J:$J,$A15,'ЕЖЕДНЕВНЫЙ УЧЕТ'!$C:$C,AL$1) -> 0 | AM15: =COUNTIFS('ЕЖЕДНЕВНЫЙ УЧЕТ'!$J:$J,$A15,'ЕЖЕДНЕВНЫЙ УЧЕТ'!$C:$C,AM$1) -> 0 | AN15: =COUNTIFS('ЕЖЕДНЕВНЫЙ УЧЕТ'!$J:$J,$A15,'ЕЖЕДНЕВНЫЙ УЧЕТ'!$C:$C,AN$1) -> 0 | AO15: =COUNTIFS('ЕЖЕДНЕВНЫЙ УЧЕТ'!$J:$J,$A15,'ЕЖЕДНЕВНЫЙ УЧЕТ'!$C:$C,AO$1) -> 1 | AP15: =COUNTIFS('ЕЖЕДНЕВНЫЙ УЧЕТ'!$J:$J,$A15,'ЕЖЕДНЕВНЫЙ УЧЕТ'!$C:$C,AP$1) -> 0 | AQ15: =COUNTIFS('ЕЖЕДНЕВНЫЙ УЧЕТ'!$J:$J,$A15,'ЕЖЕДНЕВНЫЙ УЧЕТ'!$C:$C,AQ$1) -> 0 | AR15: =COUNTIFS('ЕЖЕДНЕВНЫЙ УЧЕТ'!$J:$J,$A15,'ЕЖЕДНЕВНЫЙ УЧЕТ'!$C:$C,AR$1) -> 1 | ... AU15: =COUNTIFS('ЕЖЕДНЕВНЫЙ УЧЕТ'!$J:$J,$A15,'ЕЖЕДНЕВНЫЙ УЧЕТ'!$C:$C,AU$1) -> 0
A16: Специалист группы по подбору и адаптации | B16: =COUNTIF('ЕЖЕДНЕВНЫЙ УЧЕТ'!J:J,СВОД!A16) -> 11 | C16: =IFERROR(B16/$B$121,"") -> 0.00080409357 | E16: СЕРБИЯ | F16: =COUNTIFS('ЕЖЕДНЕВНЫЙ УЧЕТ'!$G:$G,СВОД!$E16,'ЕЖЕДНЕВНЫЙ УЧЕТ'!$Q:$Q,СВОД!F$1) -> 289 | G16: =IFERROR(F16/$F$27,"") -> 0.13677236 | H16: =COUNTIFS('ЕЖЕДНЕВНЫЙ УЧЕТ'!$G:$G,СВОД!$E16,'ЕЖЕДНЕВНЫЙ УЧЕТ'!$Q:$Q,СВОД!H$1) -> 178 | I16: =IFERROR(H16/$H$27,"") -> 0.015388606 | K16: =COUNTIFS('ЕЖЕДНЕВНЫЙ УЧЕТ'!$J:$J,$A16,'ЕЖЕДНЕВНЫЙ УЧЕТ'!$C:$C,K$1) -> 0 | L16: =COUNTIFS('ЕЖЕДНЕВНЫЙ УЧЕТ'!$J:$J,$A16,'ЕЖЕДНЕВНЫЙ УЧЕТ'!$C:$C,L$1) -> 0 | M16: =COUNTIFS('ЕЖЕДНЕВНЫЙ УЧЕТ'!$J:$J,$A16,'ЕЖЕДНЕВНЫЙ УЧЕТ'!$C:$C,M$1) -> 0 | N16: =COUNTIFS('ЕЖЕДНЕВНЫЙ УЧЕТ'!$J:$J,$A16,'ЕЖЕДНЕВНЫЙ УЧЕТ'!$C:$C,N$1) -> 0 | O16: =COUNTIFS('ЕЖЕДНЕВНЫЙ УЧЕТ'!$J:$J,$A16,'ЕЖЕДНЕВНЫЙ УЧЕТ'!$C:$C,O$1) -> 2 | P16: =COUNTIFS('ЕЖЕДНЕВНЫЙ УЧЕТ'!$J:$J,$A16,'ЕЖЕДНЕВНЫЙ УЧЕТ'!$C:$C,P$1) -> 0 | Q16: =COUNTIFS('ЕЖЕДНЕВНЫЙ УЧЕТ'!$J:$J,$A16,'ЕЖЕДНЕВНЫЙ УЧЕТ'!$C:$C,Q$1) -> 0 | R16: =COUNTIFS('ЕЖЕДНЕВНЫЙ УЧЕТ'!$J:$J,$A16,'ЕЖЕДНЕВНЫЙ УЧЕТ'!$C:$C,R$1) -> 0 | ... AU16: =COUNTIFS('ЕЖЕДНЕВНЫЙ УЧЕТ'!$J:$J,$A16,'ЕЖЕДНЕВНЫЙ УЧЕТ'!$C:$C,AU$1) -> 0
A17: Ведуший специалист группы по обучению | B17: =COUNTIF('ЕЖЕДНЕВНЫЙ УЧЕТ'!J:J,СВОД!A17) -> 0 | C17: =IFERROR(B17/$B$121,"") -> 0 | E17: СИРИЙСКАЯ АРАБСКАЯ РЕСПУБЛИКА | F17: =COUNTIFS('ЕЖЕДНЕВНЫЙ УЧЕТ'!$G:$G,СВОД!$E17,'ЕЖЕДНЕВНЫЙ УЧЕТ'!$Q:$Q,СВОД!F$1) -> 1 | G17: =IFERROR(F17/$F$27,"") -> 0.00047326077 | H17: =COUNTIFS('ЕЖЕДНЕВНЫЙ УЧЕТ'!$G:$G,СВОД!$E17,'ЕЖЕДНЕВНЫЙ УЧЕТ'!$Q:$Q,СВОД!H$1) -> 0 | I17: =IFERROR(H17/$H$27,"") -> 0 | K17: =COUNTIFS('ЕЖЕДНЕВНЫЙ УЧЕТ'!$J:$J,$A17,'ЕЖЕДНЕВНЫЙ УЧЕТ'!$C:$C,K$1) -> 0 | L17: =COUNTIFS('ЕЖЕДНЕВНЫЙ УЧЕТ'!$J:$J,$A17,'ЕЖЕДНЕВНЫЙ УЧЕТ'!$C:$C,L$1) -> 0 | M17: =COUNTIFS('ЕЖЕДНЕВНЫЙ УЧЕТ'!$J:$J,$A17,'ЕЖЕДНЕВНЫЙ УЧЕТ'!$C:$C,M$1) -> 0 | N17: =COUNTIFS('ЕЖЕДНЕВНЫЙ УЧЕТ'!$J:$J,$A17,'ЕЖЕДНЕВНЫЙ УЧЕТ'!$C:$C,N$1) -> 0 | O17: =COUNTIFS('ЕЖЕДНЕВНЫЙ УЧЕТ'!$J:$J,$A17,'ЕЖЕДНЕВНЫЙ УЧЕТ'!$C:$C,O$1) -> 0 | P17: =COUNTIFS('ЕЖЕДНЕВНЫЙ УЧЕТ'!$J:$J,$A17,'ЕЖЕДНЕВНЫЙ УЧЕТ'!$C:$C,P$1) -> 0 | Q17: =COUNTIFS('ЕЖЕДНЕВНЫЙ УЧЕТ'!$J:$J,$A17,'ЕЖЕДНЕВНЫЙ УЧЕТ'!$C:$C,Q$1) -> 0 | R17: =COUNTIFS('ЕЖЕДНЕВНЫЙ УЧЕТ'!$J:$J,$A17,'ЕЖЕДНЕВНЫЙ УЧЕТ'!$C:$C,R$1) -> 0 | ... AU17: =COUNTIFS('ЕЖЕДНЕВНЫЙ УЧЕТ'!$J:$J,$A17,'ЕЖЕДНЕВНЫЙ УЧЕТ'!$C:$C,AU$1) -> 0
A18: Специалист группы по обучению | B18: =COUNTIF('ЕЖЕДНЕВНЫЙ УЧЕТ'!J:J,СВОД!A18) -> 6 | C18: =IFERROR(B18/$B$121,"") -> 0.00043859649 | E18: ТАДЖИКИСТАН | F18: =COUNTIFS('ЕЖЕДНЕВНЫЙ УЧЕТ'!$G:$G,СВОД!$E18,'ЕЖЕДНЕВНЫЙ УЧЕТ'!$Q:$Q,СВОД!F$1) -> 35 | G18: =IFERROR(F18/$F$27,"") -> 0.016564127 | H18: =COUNTIFS('ЕЖЕДНЕВНЫЙ УЧЕТ'!$G:$G,СВОД!$E18,'ЕЖЕДНЕВНЫЙ УЧЕТ'!$Q:$Q,СВОД!H$1) -> 477 | I18: =IFERROR(H18/$H$27,"") -> 0.041238005 | K18: =COUNTIFS('ЕЖЕДНЕВНЫЙ УЧЕТ'!$J:$J,$A18,'ЕЖЕДНЕВНЫЙ УЧЕТ'!$C:$C,K$1) -> 0 | L18: =COUNTIFS('ЕЖЕДНЕВНЫЙ УЧЕТ'!$J:$J,$A18,'ЕЖЕДНЕВНЫЙ УЧЕТ'!$C:$C,L$1) -> 0 | M18: =COUNTIFS('ЕЖЕДНЕВНЫЙ УЧЕТ'!$J:$J,$A18,'ЕЖЕДНЕВНЫЙ УЧЕТ'!$C:$C,M$1) -> 0 | N18: =COUNTIFS('ЕЖЕДНЕВНЫЙ УЧЕТ'!$J:$J,$A18,'ЕЖЕДНЕВНЫЙ УЧЕТ'!$C:$C,N$1) -> 0 | O18: =COUNTIFS('ЕЖЕДНЕВНЫЙ УЧЕТ'!$J:$J,$A18,'ЕЖЕДНЕВНЫЙ УЧЕТ'!$C:$C,O$1) -> 1 | P18: =COUNTIFS('ЕЖЕДНЕВНЫЙ УЧЕТ'!$J:$J,$A18,'ЕЖЕДНЕВНЫЙ УЧЕТ'!$C:$C,P$1) -> 0 | Q18: =COUNTIFS('ЕЖЕДНЕВНЫЙ УЧЕТ'!$J:$J,$A18,'ЕЖЕДНЕВНЫЙ УЧЕТ'!$C:$C,Q$1) -> 0 | R18: =COUNTIFS('ЕЖЕДНЕВНЫЙ УЧЕТ'!$J:$J,$A18,'ЕЖЕДНЕВНЫЙ УЧЕТ'!$C:$C,R$1) -> 0 | ... AU18: =COUNTIFS('ЕЖЕДНЕВНЫЙ УЧЕТ'!$J:$J,$A18,'ЕЖЕДНЕВНЫЙ УЧЕТ'!$C:$C,AU$1) -> 0
A19: Руководитель группы мобилизации и координации | B19: =COUNTIF('ЕЖЕДНЕВНЫЙ УЧЕТ'!J:J,СВОД!A19) -> 6 | C19: =IFERROR(B19/$B$121,"") -> 0.00043859649 | E19: ТУРКМЕНИСТАН | F19: =COUNTIFS('ЕЖЕДНЕВНЫЙ УЧЕТ'!$G:$G,СВОД!$E19,'ЕЖЕДНЕВНЫЙ УЧЕТ'!$Q:$Q,СВОД!F$1) -> 16 | G19: =IFERROR(F19/$F$27,"") -> 0.0075721723 | H19: =COUNTIFS('ЕЖЕДНЕВНЫЙ УЧЕТ'!$G:$G,СВОД!$E19,'ЕЖЕДНЕВНЫЙ УЧЕТ'!$Q:$Q,СВОД!H$1) -> 1546 | I19: =IFERROR(H19/$H$27,"") -> 0.13365609 | K19: =COUNTIFS('ЕЖЕДНЕВНЫЙ УЧЕТ'!$J:$J,$A19,'ЕЖЕДНЕВНЫЙ УЧЕТ'!$C:$C,K$1) -> 0 | L19: =COUNTIFS('ЕЖЕДНЕВНЫЙ УЧЕТ'!$J:$J,$A19,'ЕЖЕДНЕВНЫЙ УЧЕТ'!$C:$C,L$1) -> 0 | M19: =COUNTIFS('ЕЖЕДНЕВНЫЙ УЧЕТ'!$J:$J,$A19,'ЕЖЕДНЕВНЫЙ УЧЕТ'!$C:$C,M$1) -> 0 | N19: =COUNTIFS('ЕЖЕДНЕВНЫЙ УЧЕТ'!$J:$J,$A19,'ЕЖЕДНЕВНЫЙ УЧЕТ'!$C:$C,N$1) -> 0 | O19: =COUNTIFS('ЕЖЕДНЕВНЫЙ УЧЕТ'!$J:$J,$A19,'ЕЖЕДНЕВНЫЙ УЧЕТ'!$C:$C,O$1) -> 1 | P19: =COUNTIFS('ЕЖЕДНЕВНЫЙ УЧЕТ'!$J:$J,$A19,'ЕЖЕДНЕВНЫЙ УЧЕТ'!$C:$C,P$1) -> 0 | Q19: =COUNTIFS('ЕЖЕДНЕВНЫЙ УЧЕТ'!$J:$J,$A19,'ЕЖЕДНЕВНЫЙ УЧЕТ'!$C:$C,Q$1) -> 0 | R19: =COUNTIFS('ЕЖЕДНЕВНЫЙ УЧЕТ'!$J:$J,$A19,'ЕЖЕДНЕВНЫЙ УЧЕТ'!$C:$C,R$1) -> 1 | ... AU19: =COUNTIFS('ЕЖЕДНЕВНЫЙ УЧЕТ'!$J:$J,$A19,'ЕЖЕДНЕВНЫЙ УЧЕТ'!$C:$C,AU$1) -> 0
A20: Главный специалист группы мобилизации и координации | B20: =COUNTIF('ЕЖЕДНЕВНЫЙ УЧЕТ'!J:J,СВОД!A20) -> 0 | C20: =IFERROR(B20/$B$121,"") -> 0 | E20: ТУРЦИЯ | F20: =COUNTIFS('ЕЖЕДНЕВНЫЙ УЧЕТ'!$G:$G,СВОД!$E20,'ЕЖЕДНЕВНЫЙ УЧЕТ'!$Q:$Q,СВОД!F$1) -> 0 | G20: =IFERROR(F20/$F$27,"") -> 0 | H20: =COUNTIFS('ЕЖЕДНЕВНЫЙ УЧЕТ'!$G:$G,СВОД!$E20,'ЕЖЕДНЕВНЫЙ УЧЕТ'!$Q:$Q,СВОД!H$1) -> 0 | I20: =IFERROR(H20/$H$27,"") -> 0 | K20: =COUNTIFS('ЕЖЕДНЕВНЫЙ УЧЕТ'!$J:$J,$A20,'ЕЖЕДНЕВНЫЙ УЧЕТ'!$C:$C,K$1) -> 0 | L20: =COUNTIFS('ЕЖЕДНЕВНЫЙ УЧЕТ'!$J:$J,$A20,'ЕЖЕДНЕВНЫЙ УЧЕТ'!$C:$C,L$1) -> 0 | M20: =COUNTIFS('ЕЖЕДНЕВНЫЙ УЧЕТ'!$J:$J,$A20,'ЕЖЕДНЕВНЫЙ УЧЕТ'!$C:$C,M$1) -> 0 | N20: =COUNTIFS('ЕЖЕДНЕВНЫЙ УЧЕТ'!$J:$J,$A20,'ЕЖЕДНЕВНЫЙ УЧЕТ'!$C:$C,N$1) -> 0 | O20: =COUNTIFS('ЕЖЕДНЕВНЫЙ УЧЕТ'!$J:$J,$A20,'ЕЖЕДНЕВНЫЙ УЧЕТ'!$C:$C,O$1) -> 0 | P20: =COUNTIFS('ЕЖЕДНЕВНЫЙ УЧЕТ'!$J:$J,$A20,'ЕЖЕДНЕВНЫЙ УЧЕТ'!$C:$C,P$1) -> 0 | Q20: =COUNTIFS('ЕЖЕДНЕВНЫЙ УЧЕТ'!$J:$J,$A20,'ЕЖЕДНЕВНЫЙ УЧЕТ'!$C:$C,Q$1) -> 0 | R20: =COUNTIFS('ЕЖЕДНЕВНЫЙ УЧЕТ'!$J:$J,$A20,'ЕЖЕДНЕВНЫЙ УЧЕТ'!$C:$C,R$1) -> 0 | ... AU20: =COUNTIFS('ЕЖЕДНЕВНЫЙ УЧЕТ'!$J:$J,$A20,'ЕЖЕДНЕВНЫЙ УЧЕТ'!$C:$C,AU$1) -> 0
A21: Ведущий специалист группы мобилизации и координации | B21: =COUNTIF('ЕЖЕДНЕВНЫЙ УЧЕТ'!J:J,СВОД!A21) -> 10 | C21: =IFERROR(B21/$B$121,"") -> 0.00073099415 | E21: УЗБЕКИСТАН | F21: =COUNTIFS('ЕЖЕДНЕВНЫЙ УЧЕТ'!$G:$G,СВОД!$E21,'ЕЖЕДНЕВНЫЙ УЧЕТ'!$Q:$Q,СВОД!F$1) -> 91 | G21: =IFERROR(F21/$F$27,"") -> 0.04306673 | H21: =COUNTIFS('ЕЖЕДНЕВНЫЙ УЧЕТ'!$G:$G,СВОД!$E21,'ЕЖЕДНЕВНЫЙ УЧЕТ'!$Q:$Q,СВОД!H$1) -> 2739 | I21: =IFERROR(H21/$H$27,"") -> 0.23679433 | K21: =COUNTIFS('ЕЖЕДНЕВНЫЙ УЧЕТ'!$J:$J,$A21,'ЕЖЕДНЕВНЫЙ УЧЕТ'!$C:$C,K$1) -> 0 | L21: =COUNTIFS('ЕЖЕДНЕВНЫЙ УЧЕТ'!$J:$J,$A21,'ЕЖЕДНЕВНЫЙ УЧЕТ'!$C:$C,L$1) -> 0 | M21: =COUNTIFS('ЕЖЕДНЕВНЫЙ УЧЕТ'!$J:$J,$A21,'ЕЖЕДНЕВНЫЙ УЧЕТ'!$C:$C,M$1) -> 0 | N21: =COUNTIFS('ЕЖЕДНЕВНЫЙ УЧЕТ'!$J:$J,$A21,'ЕЖЕДНЕВНЫЙ УЧЕТ'!$C:$C,N$1) -> 0 | O21: =COUNTIFS('ЕЖЕДНЕВНЫЙ УЧЕТ'!$J:$J,$A21,'ЕЖЕДНЕВНЫЙ УЧЕТ'!$C:$C,O$1) -> 0 | P21: =COUNTIFS('ЕЖЕДНЕВНЫЙ УЧЕТ'!$J:$J,$A21,'ЕЖЕДНЕВНЫЙ УЧЕТ'!$C:$C,P$1) -> 0 | Q21: =COUNTIFS('ЕЖЕДНЕВНЫЙ УЧЕТ'!$J:$J,$A21,'ЕЖЕДНЕВНЫЙ УЧЕТ'!$C:$C,Q$1) -> 0 | R21: =COUNTIFS('ЕЖЕДНЕВНЫЙ УЧЕТ'!$J:$J,$A21,'ЕЖЕДНЕВНЫЙ УЧЕТ'!$C:$C,R$1) -> 0 | ... AU21: =COUNTIFS('ЕЖЕДНЕВНЫЙ УЧЕТ'!$J:$J,$A21,'ЕЖЕДНЕВНЫЙ УЧЕТ'!$C:$C,AU$1) -> 0
A22: Специалист группы мобилизации и координации | B22: =COUNTIF('ЕЖЕДНЕВНЫЙ УЧЕТ'!J:J,СВОД!A22) -> 34 | C22: =IFERROR(B22/$B$121,"") -> 0.0024853801 | E22: УКРАИНА | F22: =COUNTIFS('ЕЖЕДНЕВНЫЙ УЧЕТ'!$G:$G,СВОД!$E22,'ЕЖЕДНЕВНЫЙ УЧЕТ'!$Q:$Q,СВОД!F$1) -> 0 | G22: =IFERROR(F22/$F$27,"") -> 0 | H22: =COUNTIFS('ЕЖЕДНЕВНЫЙ УЧЕТ'!$G:$G,СВОД!$E22,'ЕЖЕДНЕВНЫЙ УЧЕТ'!$Q:$Q,СВОД!H$1) -> 0 | I22: =IFERROR(H22/$H$27,"") -> 0 | K22: =COUNTIFS('ЕЖЕДНЕВНЫЙ УЧЕТ'!$J:$J,$A22,'ЕЖЕДНЕВНЫЙ УЧЕТ'!$C:$C,K$1) -> 0 | L22: =COUNTIFS('ЕЖЕДНЕВНЫЙ УЧЕТ'!$J:$J,$A22,'ЕЖЕДНЕВНЫЙ УЧЕТ'!$C:$C,L$1) -> 0 | M22: =COUNTIFS('ЕЖЕДНЕВНЫЙ УЧЕТ'!$J:$J,$A22,'ЕЖЕДНЕВНЫЙ УЧЕТ'!$C:$C,M$1) -> 0 | N22: =COUNTIFS('ЕЖЕДНЕВНЫЙ УЧЕТ'!$J:$J,$A22,'ЕЖЕДНЕВНЫЙ УЧЕТ'!$C:$C,N$1) -> 0 | O22: =COUNTIFS('ЕЖЕДНЕВНЫЙ УЧЕТ'!$J:$J,$A22,'ЕЖЕДНЕВНЫЙ УЧЕТ'!$C:$C,O$1) -> 2 | P22: =COUNTIFS('ЕЖЕДНЕВНЫЙ УЧЕТ'!$J:$J,$A22,'ЕЖЕДНЕВНЫЙ УЧЕТ'!$C:$C,P$1) -> 0 | Q22: =COUNTIFS('ЕЖЕДНЕВНЫЙ УЧЕТ'!$J:$J,$A22,'ЕЖЕДНЕВНЫЙ УЧЕТ'!$C:$C,Q$1) -> 1 | R22: =COUNTIFS('ЕЖЕДНЕВНЫЙ УЧЕТ'!$J:$J,$A22,'ЕЖЕДНЕВНЫЙ УЧЕТ'!$C:$C,R$1) -> 0 | ... AU22: =COUNTIFS('ЕЖЕДНЕВНЫЙ УЧЕТ'!$J:$J,$A22,'ЕЖЕДНЕВНЫЙ УЧЕТ'!$C:$C,AU$1) -> 0
A23: Диспетчер группы мобилизации и координации | B23: =COUNTIF('ЕЖЕДНЕВНЫЙ УЧЕТ'!J:J,СВОД!A23) -> 20 | C23: =IFERROR(B23/$B$121,"") -> 0.0014619883 | E23: ХОРВАТИЯ | F23: =COUNTIFS('ЕЖЕДНЕВНЫЙ УЧЕТ'!$G:$G,СВОД!$E23,'ЕЖЕДНЕВНЫЙ УЧЕТ'!$Q:$Q,СВОД!F$1) -> 0 | G23: =IFERROR(F23/$F$27,"") -> 0 | H23: =COUNTIFS('ЕЖЕДНЕВНЫЙ УЧЕТ'!$G:$G,СВОД!$E23,'ЕЖЕДНЕВНЫЙ УЧЕТ'!$Q:$Q,СВОД!H$1) -> 0 | I23: =IFERROR(H23/$H$27,"") -> 0 | K23: =COUNTIFS('ЕЖЕДНЕВНЫЙ УЧЕТ'!$J:$J,$A23,'ЕЖЕДНЕВНЫЙ УЧЕТ'!$C:$C,K$1) -> 0 | L23: =COUNTIFS('ЕЖЕДНЕВНЫЙ УЧЕТ'!$J:$J,$A23,'ЕЖЕДНЕВНЫЙ УЧЕТ'!$C:$C,L$1) -> 0 | M23: =COUNTIFS('ЕЖЕДНЕВНЫЙ УЧЕТ'!$J:$J,$A23,'ЕЖЕДНЕВНЫЙ УЧЕТ'!$C:$C,M$1) -> 0 | N23: =COUNTIFS('ЕЖЕДНЕВНЫЙ УЧЕТ'!$J:$J,$A23,'ЕЖЕДНЕВНЫЙ УЧЕТ'!$C:$C,N$1) -> 0 | O23: =COUNTIFS('ЕЖЕДНЕВНЫЙ УЧЕТ'!$J:$J,$A23,'ЕЖЕДНЕВНЫЙ УЧЕТ'!$C:$C,O$1) -> 6 | P23: =COUNTIFS('ЕЖЕДНЕВНЫЙ УЧЕТ'!$J:$J,$A23,'ЕЖЕДНЕВНЫЙ УЧЕТ'!$C:$C,P$1) -> 0 | Q23: =COUNTIFS('ЕЖЕДНЕВНЫЙ УЧЕТ'!$J:$J,$A23,'ЕЖЕДНЕВНЫЙ УЧЕТ'!$C:$C,Q$1) -> 0 | R23: =COUNTIFS('ЕЖЕДНЕВНЫЙ УЧЕТ'!$J:$J,$A23,'ЕЖЕДНЕВНЫЙ УЧЕТ'!$C:$C,R$1) -> 0 | ... AU23: =COUNTIFS('ЕЖЕДНЕВНЫЙ УЧЕТ'!$J:$J,$A23,'ЕЖЕДНЕВНЫЙ УЧЕТ'!$C:$C,AU$1) -> 0
A24: Руководитель группы экономики труда | B24: =COUNTIF('ЕЖЕДНЕВНЫЙ УЧЕТ'!J:J,СВОД!A24) -> 1 | C24: =IFERROR(B24/$B$121,"") -> 7.3099415e-05 | E24: ЧЕРНОГОРИЯ | F24: =COUNTIFS('ЕЖЕДНЕВНЫЙ УЧЕТ'!$G:$G,СВОД!$E24,'ЕЖЕДНЕВНЫЙ УЧЕТ'!$Q:$Q,СВОД!F$1) -> 1 | G24: =IFERROR(F24/$F$27,"") -> 0.00047326077 | H24: =COUNTIFS('ЕЖЕДНЕВНЫЙ УЧЕТ'!$G:$G,СВОД!$E24,'ЕЖЕДНЕВНЫЙ УЧЕТ'!$Q:$Q,СВОД!H$1) -> 0 | I24: =IFERROR(H24/$H$27,"") -> 0 | K24: =COUNTIFS('ЕЖЕДНЕВНЫЙ УЧЕТ'!$J:$J,$A24,'ЕЖЕДНЕВНЫЙ УЧЕТ'!$C:$C,K$1) -> 0 | L24: =COUNTIFS('ЕЖЕДНЕВНЫЙ УЧЕТ'!$J:$J,$A24,'ЕЖЕДНЕВНЫЙ УЧЕТ'!$C:$C,L$1) -> 0 | M24: =COUNTIFS('ЕЖЕДНЕВНЫЙ УЧЕТ'!$J:$J,$A24,'ЕЖЕДНЕВНЫЙ УЧЕТ'!$C:$C,M$1) -> 0 | N24: =COUNTIFS('ЕЖЕДНЕВНЫЙ УЧЕТ'!$J:$J,$A24,'ЕЖЕДНЕВНЫЙ УЧЕТ'!$C:$C,N$1) -> 0 | O24: =COUNTIFS('ЕЖЕДНЕВНЫЙ УЧЕТ'!$J:$J,$A24,'ЕЖЕДНЕВНЫЙ УЧЕТ'!$C:$C,O$1) -> 0 | P24: =COUNTIFS('ЕЖЕДНЕВНЫЙ УЧЕТ'!$J:$J,$A24,'ЕЖЕДНЕВНЫЙ УЧЕТ'!$C:$C,P$1) -> 0 | Q24: =COUNTIFS('ЕЖЕДНЕВНЫЙ УЧЕТ'!$J:$J,$A24,'ЕЖЕДНЕВНЫЙ УЧЕТ'!$C:$C,Q$1) -> 0 | R24: =COUNTIFS('ЕЖЕДНЕВНЫЙ УЧЕТ'!$J:$J,$A24,'ЕЖЕДНЕВНЫЙ УЧЕТ'!$C:$C,R$1) -> 0 | ... AU24: =COUNTIFS('ЕЖЕДНЕВНЫЙ УЧЕТ'!$J:$J,$A24,'ЕЖЕДНЕВНЫЙ УЧЕТ'!$C:$C,AU$1) -> 0
A25: Ведущий экономист по труду | B25: =COUNTIF('ЕЖЕДНЕВНЫЙ УЧЕТ'!J:J,СВОД!A25) -> 3 | C25: =IFERROR(B25/$B$121,"") -> 0.00021929825 | K25: =COUNTIFS('ЕЖЕДНЕВНЫЙ УЧЕТ'!$J:$J,$A25,'ЕЖЕДНЕВНЫЙ УЧЕТ'!$C:$C,K$1) -> 0 | L25: =COUNTIFS('ЕЖЕДНЕВНЫЙ УЧЕТ'!$J:$J,$A25,'ЕЖЕДНЕВНЫЙ УЧЕТ'!$C:$C,L$1) -> 0 | M25: =COUNTIFS('ЕЖЕДНЕВНЫЙ УЧЕТ'!$J:$J,$A25,'ЕЖЕДНЕВНЫЙ УЧЕТ'!$C:$C,M$1) -> 0 | N25: =COUNTIFS('ЕЖЕДНЕВНЫЙ УЧЕТ'!$J:$J,$A25,'ЕЖЕДНЕВНЫЙ УЧЕТ'!$C:$C,N$1) -> 0 | O25: =COUNTIFS('ЕЖЕДНЕВНЫЙ УЧЕТ'!$J:$J,$A25,'ЕЖЕДНЕВНЫЙ УЧЕТ'!$C:$C,O$1) -> 1 | P25: =COUNTIFS('ЕЖЕДНЕВНЫЙ УЧЕТ'!$J:$J,$A25,'ЕЖЕДНЕВНЫЙ УЧЕТ'!$C:$C,P$1) -> 0 | Q25: =COUNTIFS('ЕЖЕДНЕВНЫЙ УЧЕТ'!$J:$J,$A25,'ЕЖЕДНЕВНЫЙ УЧЕТ'!$C:$C,Q$1) -> 0 | R25: =COUNTIFS('ЕЖЕДНЕВНЫЙ УЧЕТ'!$J:$J,$A25,'ЕЖЕДНЕВНЫЙ УЧЕТ'!$C:$C,R$1) -> 0 | ... AU25: =COUNTIFS('ЕЖЕДНЕВНЫЙ УЧЕТ'!$J:$J,$A25,'ЕЖЕДНЕВНЫЙ УЧЕТ'!$C:$C,AU$1) -> 0
A26: Экономист по труду | B26: =COUNTIF('ЕЖЕДНЕВНЫЙ УЧЕТ'!J:J,СВОД!A26) -> 8 | C26: =IFERROR(B26/$B$121,"") -> 0.00058479532 | K26: =COUNTIFS('ЕЖЕДНЕВНЫЙ УЧЕТ'!$J:$J,$A26,'ЕЖЕДНЕВНЫЙ УЧЕТ'!$C:$C,K$1) -> 0 | L26: =COUNTIFS('ЕЖЕДНЕВНЫЙ УЧЕТ'!$J:$J,$A26,'ЕЖЕДНЕВНЫЙ УЧЕТ'!$C:$C,L$1) -> 0 | M26: =COUNTIFS('ЕЖЕДНЕВНЫЙ УЧЕТ'!$J:$J,$A26,'ЕЖЕДНЕВНЫЙ УЧЕТ'!$C:$C,M$1) -> 0 | N26: =COUNTIFS('ЕЖЕДНЕВНЫЙ УЧЕТ'!$J:$J,$A26,'ЕЖЕДНЕВНЫЙ УЧЕТ'!$C:$C,N$1) -> 0 | O26: =COUNTIFS('ЕЖЕДНЕВНЫЙ УЧЕТ'!$J:$J,$A26,'ЕЖЕДНЕВНЫЙ УЧЕТ'!$C:$C,O$1) -> 1 | P26: =COUNTIFS('ЕЖЕДНЕВНЫЙ УЧЕТ'!$J:$J,$A26,'ЕЖЕДНЕВНЫЙ УЧЕТ'!$C:$C,P$1) -> 0 | Q26: =COUNTIFS('ЕЖЕДНЕВНЫЙ УЧЕТ'!$J:$J,$A26,'ЕЖЕДНЕВНЫЙ УЧЕТ'!$C:$C,Q$1) -> 0 | R26: =COUNTIFS('ЕЖЕДНЕВНЫЙ УЧЕТ'!$J:$J,$A26,'ЕЖЕДНЕВНЫЙ УЧЕТ'!$C:$C,R$1) -> 0 | ... AU26: =COUNTIFS('ЕЖЕДНЕВНЫЙ УЧЕТ'!$J:$J,$A26,'ЕЖЕДНЕВНЫЙ УЧЕТ'!$C:$C,AU$1) -> 0
A27: Экономист | B27: =COUNTIF('ЕЖЕДНЕВНЫЙ УЧЕТ'!J:J,СВОД!A27) -> 0 | C27: =IFERROR(B27/$B$121,"") -> 0 | E27: ИТОГО | F27: =SUM(F2:F24) -> 2113 | H27: =SUM(H2:H24) -> 11567 | I27: =SUM(F27:H27)='ЕЖЕДНЕВНЫЙ УЧЕТ'!G2 -> TRUE | K27: =COUNTIFS('ЕЖЕДНЕВНЫЙ УЧЕТ'!$J:$J,$A27,'ЕЖЕДНЕВНЫЙ УЧЕТ'!$C:$C,K$1) -> 0 | L27: =COUNTIFS('ЕЖЕДНЕВНЫЙ УЧЕТ'!$J:$J,$A27,'ЕЖЕДНЕВНЫЙ УЧЕТ'!$C:$C,L$1) -> 0 | M27: =COUNTIFS('ЕЖЕДНЕВНЫЙ УЧЕТ'!$J:$J,$A27,'ЕЖЕДНЕВНЫЙ УЧЕТ'!$C:$C,M$1) -> 0 | N27: =COUNTIFS('ЕЖЕДНЕВНЫЙ УЧЕТ'!$J:$J,$A27,'ЕЖЕДНЕВНЫЙ УЧЕТ'!$C:$C,N$1) -> 0 | O27: =COUNTIFS('ЕЖЕДНЕВНЫЙ УЧЕТ'!$J:$J,$A27,'ЕЖЕДНЕВНЫЙ УЧЕТ'!$C:$C,O$1) -> 0 | P27: =COUNTIFS('ЕЖЕДНЕВНЫЙ УЧЕТ'!$J:$J,$A27,'ЕЖЕДНЕВНЫЙ УЧЕТ'!$C:$C,P$1) -> 0 | Q27: =COUNTIFS('ЕЖЕДНЕВНЫЙ УЧЕТ'!$J:$J,$A27,'ЕЖЕДНЕВНЫЙ УЧЕТ'!$C:$C,Q$1) -> 0 | R27: =COUNTIFS('ЕЖЕДНЕВНЫЙ УЧЕТ'!$J:$J,$A27,'ЕЖЕДНЕВНЫЙ УЧЕТ'!$C:$C,R$1) -> 0 | ... AU27: =COUNTIFS('ЕЖЕДНЕВНЫЙ УЧЕТ'!$J:$J,$A27,'ЕЖЕДНЕВНЫЙ УЧЕТ'!$C:$C,AU$1) -> 0
A28: Делопроизводитель | B28: =COUNTIF('ЕЖЕДНЕВНЫЙ УЧЕТ'!J:J,СВОД!A28) -> 0 | C28: =IFERROR(B28/$B$121,"") -> 0 | K28: =COUNTIFS('ЕЖЕДНЕВНЫЙ УЧЕТ'!$J:$J,$A28,'ЕЖЕДНЕВНЫЙ УЧЕТ'!$C:$C,K$1) -> 0 | L28: =COUNTIFS('ЕЖЕДНЕВНЫЙ УЧЕТ'!$J:$J,$A28,'ЕЖЕДНЕВНЫЙ УЧЕТ'!$C:$C,L$1) -> 0 | M28: =COUNTIFS('ЕЖЕДНЕВНЫЙ УЧЕТ'!$J:$J,$A28,'ЕЖЕДНЕВНЫЙ УЧЕТ'!$C:$C,M$1) -> 0 | N28: =COUNTIFS('ЕЖЕДНЕВНЫЙ УЧЕТ'!$J:$J,$A28,'ЕЖЕДНЕВНЫЙ УЧЕТ'!$C:$C,N$1) -> 0 | O28: =COUNTIFS('ЕЖЕДНЕВНЫЙ УЧЕТ'!$J:$J,$A28,'ЕЖЕДНЕВНЫЙ УЧЕТ'!$C:$C,O$1) -> 0 | P28: =COUNTIFS('ЕЖЕДНЕВНЫЙ УЧЕТ'!$J:$J,$A28,'ЕЖЕДНЕВНЫЙ УЧЕТ'!$C:$C,P$1) -> 0 | Q28: =COUNTIFS('ЕЖЕДНЕВНЫЙ УЧЕТ'!$J:$J,$A28,'ЕЖЕДНЕВНЫЙ УЧЕТ'!$C:$C,Q$1) -> 0 | R28: =COUNTIFS('ЕЖЕДНЕВНЫЙ УЧЕТ'!$J:$J,$A28,'ЕЖЕДНЕВНЫЙ УЧЕТ'!$C:$C,R$1) -> 0 | ... AU28: =COUNTIFS('ЕЖЕДНЕВНЫЙ УЧЕТ'!$J:$J,$A28,'ЕЖЕДНЕВНЫЙ УЧЕТ'!$C:$C,AU$1) -> 0
A29: Секретарь руководителя | B29: =COUNTIF('ЕЖЕДНЕВНЫЙ УЧЕТ'!J:J,СВОД!A29) -> 6 | C29: =IFERROR(B29/$B$121,"") -> 0.00043859649 | E29: Участок/Отдел | F29: ITR | G29: ITR% | H29: R | I29: R% | K29: =COUNTIFS('ЕЖЕДНЕВНЫЙ УЧЕТ'!$J:$J,$A29,'ЕЖЕДНЕВНЫЙ УЧЕТ'!$C:$C,K$1) -> 0 | L29: =COUNTIFS('ЕЖЕДНЕВНЫЙ УЧЕТ'!$J:$J,$A29,'ЕЖЕДНЕВНЫЙ УЧЕТ'!$C:$C,L$1) -> 0 | M29: =COUNTIFS('ЕЖЕДНЕВНЫЙ УЧЕТ'!$J:$J,$A29,'ЕЖЕДНЕВНЫЙ УЧЕТ'!$C:$C,M$1) -> 0 | N29: =COUNTIFS('ЕЖЕДНЕВНЫЙ УЧЕТ'!$J:$J,$A29,'ЕЖЕДНЕВНЫЙ УЧЕТ'!$C:$C,N$1) -> 0 | O29: =COUNTIFS('ЕЖЕДНЕВНЫЙ УЧЕТ'!$J:$J,$A29,'ЕЖЕДНЕВНЫЙ УЧЕТ'!$C:$C,O$1) -> 0 | P29: =COUNTIFS('ЕЖЕДНЕВНЫЙ УЧЕТ'!$J:$J,$A29,'ЕЖЕДНЕВНЫЙ УЧЕТ'!$C:$C,P$1) -> 0 | Q29: =COUNTIFS('ЕЖЕДНЕВНЫЙ УЧЕТ'!$J:$J,$A29,'ЕЖЕДНЕВНЫЙ УЧЕТ'!$C:$C,Q$1) -> 0 | R29: =COUNTIFS('ЕЖЕДНЕВНЫЙ УЧЕТ'!$J:$J,$A29,'ЕЖЕДНЕВНЫЙ УЧЕТ'!$C:$C,R$1) -> 0 | ... AU29: =COUNTIFS('ЕЖЕДНЕВНЫЙ УЧЕТ'!$J:$J,$A29,'ЕЖЕДНЕВНЫЙ УЧЕТ'!$C:$C,AU$1) -> 0
A30: Старший бухгалтер | B30: =COUNTIF('ЕЖЕДНЕВНЫЙ УЧЕТ'!J:J,СВОД!A30) -> 0 | C30: =IFERROR(B30/$B$121,"") -> 0 | E30: АУП | F30: =COUNTIFS('ЕЖЕДНЕВНЫЙ УЧЕТ'!$K:$K,СВОД!$E30,'ЕЖЕДНЕВНЫЙ УЧЕТ'!$Q:$Q,СВОД!F$1) -> 1233 | G30: =IFERROR(F30/$F$48,"") -> 0.58353053 | H30: =COUNTIFS('ЕЖЕДНЕВНЫЙ УЧЕТ'!$K:$K,СВОД!$E30,'ЕЖЕДНЕВНЫЙ УЧЕТ'!$Q:$Q,СВОД!H$1) -> 0 | I30: =IFERROR(H30/$H$48,"") -> 0 | K30: =COUNTIFS('ЕЖЕДНЕВНЫЙ УЧЕТ'!$J:$J,$A30,'ЕЖЕДНЕВНЫЙ УЧЕТ'!$C:$C,K$1) -> 0 | L30: =COUNTIFS('ЕЖЕДНЕВНЫЙ УЧЕТ'!$J:$J,$A30,'ЕЖЕДНЕВНЫЙ УЧЕТ'!$C:$C,L$1) -> 0 | M30: =COUNTIFS('ЕЖЕДНЕВНЫЙ УЧЕТ'!$J:$J,$A30,'ЕЖЕДНЕВНЫЙ УЧЕТ'!$C:$C,M$1) -> 0 | N30: =COUNTIFS('ЕЖЕДНЕВНЫЙ УЧЕТ'!$J:$J,$A30,'ЕЖЕДНЕВНЫЙ УЧЕТ'!$C:$C,N$1) -> 0 | O30: =COUNTIFS('ЕЖЕДНЕВНЫЙ УЧЕТ'!$J:$J,$A30,'ЕЖЕДНЕВНЫЙ УЧЕТ'!$C:$C,O$1) -> 0 | P30: =COUNTIFS('ЕЖЕДНЕВНЫЙ УЧЕТ'!$J:$J,$A30,'ЕЖЕДНЕВНЫЙ УЧЕТ'!$C:$C,P$1) -> 0 | Q30: =COUNTIFS('ЕЖЕДНЕВНЫЙ УЧЕТ'!$J:$J,$A30,'ЕЖЕДНЕВНЫЙ УЧЕТ'!$C:$C,Q$1) -> 0 | R30: =COUNTIFS('ЕЖЕДНЕВНЫЙ УЧЕТ'!$J:$J,$A30,'ЕЖЕДНЕВНЫЙ УЧЕТ'!$C:$C,R$1) -> 0 | ... AU30: =COUNTIFS('ЕЖЕДНЕВНЫЙ УЧЕТ'!$J:$J,$A30,'ЕЖЕДНЕВНЫЙ УЧЕТ'!$C:$C,AU$1) -> 0
A31: Бухгалтер | B31: =COUNTIF('ЕЖЕДНЕВНЫЙ УЧЕТ'!J:J,СВОД!A31) -> 9 | C31: =IFERROR(B31/$B$121,"") -> 0.00065789474 | E31: ВП и НП | F31: =COUNTIFS('ЕЖЕДНЕВНЫЙ УЧЕТ'!$K:$K,СВОД!$E31,'ЕЖЕДНЕВНЫЙ УЧЕТ'!$Q:$Q,СВОД!F$1) -> 116 | G31: =IFERROR(F31/$F$48,"") -> 0.054898249 | H31: =COUNTIFS('ЕЖЕДНЕВНЫЙ УЧЕТ'!$K:$K,СВОД!$E31,'ЕЖЕДНЕВНЫЙ УЧЕТ'!$Q:$Q,СВОД!H$1) -> 0 | I31: =IFERROR(H31/$H$48,"") -> 0 | K31: =COUNTIFS('ЕЖЕДНЕВНЫЙ УЧЕТ'!$J:$J,$A31,'ЕЖЕДНЕВНЫЙ УЧЕТ'!$C:$C,K$1) -> 0 | L31: =COUNTIFS('ЕЖЕДНЕВНЫЙ УЧЕТ'!$J:$J,$A31,'ЕЖЕДНЕВНЫЙ УЧЕТ'!$C:$C,L$1) -> 0 | M31: =COUNTIFS('ЕЖЕДНЕВНЫЙ УЧЕТ'!$J:$J,$A31,'ЕЖЕДНЕВНЫЙ УЧЕТ'!$C:$C,M$1) -> 0 | N31: =COUNTIFS('ЕЖЕДНЕВНЫЙ УЧЕТ'!$J:$J,$A31,'ЕЖЕДНЕВНЫЙ УЧЕТ'!$C:$C,N$1) -> 0 | O31: =COUNTIFS('ЕЖЕДНЕВНЫЙ УЧЕТ'!$J:$J,$A31,'ЕЖЕДНЕВНЫЙ УЧЕТ'!$C:$C,O$1) -> 0 | P31: =COUNTIFS('ЕЖЕДНЕВНЫЙ УЧЕТ'!$J:$J,$A31,'ЕЖЕДНЕВНЫЙ УЧЕТ'!$C:$C,P$1) -> 0 | Q31: =COUNTIFS('ЕЖЕДНЕВНЫЙ УЧЕТ'!$J:$J,$A31,'ЕЖЕДНЕВНЫЙ УЧЕТ'!$C:$C,Q$1) -> 0 | R31: =COUNTIFS('ЕЖЕДНЕВНЫЙ УЧЕТ'!$J:$J,$A31,'ЕЖЕДНЕВНЫЙ УЧЕТ'!$C:$C,R$1) -> 0 | ... AU31: =COUNTIFS('ЕЖЕДНЕВНЫЙ УЧЕТ'!$J:$J,$A31,'ЕЖЕДНЕВНЫЙ УЧЕТ'!$C:$C,AU$1) -> 0
A32: Начальник ОТ ПБ и ООС | B32: =COUNTIF('ЕЖЕДНЕВНЫЙ УЧЕТ'!J:J,СВОД!A32) -> 11 | C32: =IFERROR(B32/$B$121,"") -> 0.00080409357 | E32: СМУ | F32: =COUNTIFS('ЕЖЕДНЕВНЫЙ УЧЕТ'!$K:$K,СВОД!$E32,'ЕЖЕДНЕВНЫЙ УЧЕТ'!$Q:$Q,СВОД!F$1) -> 0 | G32: =IFERROR(F32/$F$48,"") -> 0 | H32: =COUNTIFS('ЕЖЕДНЕВНЫЙ УЧЕТ'!$K:$K,СВОД!$E32,'ЕЖЕДНЕВНЫЙ УЧЕТ'!$Q:$Q,СВОД!H$1) -> 0 | I32: =IFERROR(H32/$H$48,"") -> 0 | K32: =COUNTIFS('ЕЖЕДНЕВНЫЙ УЧЕТ'!$J:$J,$A32,'ЕЖЕДНЕВНЫЙ УЧЕТ'!$C:$C,K$1) -> 0 | L32: =COUNTIFS('ЕЖЕДНЕВНЫЙ УЧЕТ'!$J:$J,$A32,'ЕЖЕДНЕВНЫЙ УЧЕТ'!$C:$C,L$1) -> 0 | M32: =COUNTIFS('ЕЖЕДНЕВНЫЙ УЧЕТ'!$J:$J,$A32,'ЕЖЕДНЕВНЫЙ УЧЕТ'!$C:$C,M$1) -> 0 | N32: =COUNTIFS('ЕЖЕДНЕВНЫЙ УЧЕТ'!$J:$J,$A32,'ЕЖЕДНЕВНЫЙ УЧЕТ'!$C:$C,N$1) -> 0 | O32: =COUNTIFS('ЕЖЕДНЕВНЫЙ УЧЕТ'!$J:$J,$A32,'ЕЖЕДНЕВНЫЙ УЧЕТ'!$C:$C,O$1) -> 1 | P32: =COUNTIFS('ЕЖЕДНЕВНЫЙ УЧЕТ'!$J:$J,$A32,'ЕЖЕДНЕВНЫЙ УЧЕТ'!$C:$C,P$1) -> 0 | Q32: =COUNTIFS('ЕЖЕДНЕВНЫЙ УЧЕТ'!$J:$J,$A32,'ЕЖЕДНЕВНЫЙ УЧЕТ'!$C:$C,Q$1) -> 1 | R32: =COUNTIFS('ЕЖЕДНЕВНЫЙ УЧЕТ'!$J:$J,$A32,'ЕЖЕДНЕВНЫЙ УЧЕТ'!$C:$C,R$1) -> 0 | ... AU32: =COUNTIFS('ЕЖЕДНЕВНЫЙ УЧЕТ'!$J:$J,$A32,'ЕЖЕДНЕВНЫЙ УЧЕТ'!$C:$C,AU$1) -> 0
A33: Заместитель начальника ОТ ПБ и ООС | B33: =COUNTIF('ЕЖЕДНЕВНЫЙ УЧЕТ'!J:J,СВОД!A33) -> 5 | C33: =IFERROR(B33/$B$121,"") -> 0.00036549708 | E33: Участок ТТ | F33: =COUNTIFS('ЕЖЕДНЕВНЫЙ УЧЕТ'!$K:$K,СВОД!$E33,'ЕЖЕДНЕВНЫЙ УЧЕТ'!$Q:$Q,СВОД!F$1) -> 0 | G33: =IFERROR(F33/$F$48,"") -> 0 | H33: =COUNTIFS('ЕЖЕДНЕВНЫЙ УЧЕТ'!$K:$K,СВОД!$E33,'ЕЖЕДНЕВНЫЙ УЧЕТ'!$Q:$Q,СВОД!H$1) -> 0 | I33: =IFERROR(H33/$H$48,"") -> 0 | K33: =COUNTIFS('ЕЖЕДНЕВНЫЙ УЧЕТ'!$J:$J,$A33,'ЕЖЕДНЕВНЫЙ УЧЕТ'!$C:$C,K$1) -> 0 | L33: =COUNTIFS('ЕЖЕДНЕВНЫЙ УЧЕТ'!$J:$J,$A33,'ЕЖЕДНЕВНЫЙ УЧЕТ'!$C:$C,L$1) -> 0 | M33: =COUNTIFS('ЕЖЕДНЕВНЫЙ УЧЕТ'!$J:$J,$A33,'ЕЖЕДНЕВНЫЙ УЧЕТ'!$C:$C,M$1) -> 0 | N33: =COUNTIFS('ЕЖЕДНЕВНЫЙ УЧЕТ'!$J:$J,$A33,'ЕЖЕДНЕВНЫЙ УЧЕТ'!$C:$C,N$1) -> 0 | O33: =COUNTIFS('ЕЖЕДНЕВНЫЙ УЧЕТ'!$J:$J,$A33,'ЕЖЕДНЕВНЫЙ УЧЕТ'!$C:$C,O$1) -> 0 | P33: =COUNTIFS('ЕЖЕДНЕВНЫЙ УЧЕТ'!$J:$J,$A33,'ЕЖЕДНЕВНЫЙ УЧЕТ'!$C:$C,P$1) -> 0 | Q33: =COUNTIFS('ЕЖЕДНЕВНЫЙ УЧЕТ'!$J:$J,$A33,'ЕЖЕДНЕВНЫЙ УЧЕТ'!$C:$C,Q$1) -> 0 | R33: =COUNTIFS('ЕЖЕДНЕВНЫЙ УЧЕТ'!$J:$J,$A33,'ЕЖЕДНЕВНЫЙ УЧЕТ'!$C:$C,R$1) -> 1 | ... AU33: =COUNTIFS('ЕЖЕДНЕВНЫЙ УЧЕТ'!$J:$J,$A33,'ЕЖЕДНЕВНЫЙ УЧЕТ'!$C:$C,AU$1) -> 0
A34: Специалист по охране труда (офис) | B34: =COUNTIF('ЕЖЕДНЕВНЫЙ УЧЕТ'!J:J,СВОД!A34) -> 26 | C34: =IFERROR(B34/$B$121,"") -> 0.0019005848 | E34: Участок МБР | F34: =COUNTIFS('ЕЖЕДНЕВНЫЙ УЧЕТ'!$K:$K,СВОД!$E34,'ЕЖЕДНЕВНЫЙ УЧЕТ'!$Q:$Q,СВОД!F$1) -> 309 | G34: =IFERROR(F34/$F$48,"") -> 0.14623758 | H34: =COUNTIFS('ЕЖЕДНЕВНЫЙ УЧЕТ'!$K:$K,СВОД!$E34,'ЕЖЕДНЕВНЫЙ УЧЕТ'!$Q:$Q,СВОД!H$1) -> 4121 | I34: =IFERROR(H34/$H$48,"") -> 0.35627215 | K34: =COUNTIFS('ЕЖЕДНЕВНЫЙ УЧЕТ'!$J:$J,$A34,'ЕЖЕДНЕВНЫЙ УЧЕТ'!$C:$C,K$1) -> 0 | L34: =COUNTIFS('ЕЖЕДНЕВНЫЙ УЧЕТ'!$J:$J,$A34,'ЕЖЕДНЕВНЫЙ УЧЕТ'!$C:$C,L$1) -> 0 | M34: =COUNTIFS('ЕЖЕДНЕВНЫЙ УЧЕТ'!$J:$J,$A34,'ЕЖЕДНЕВНЫЙ УЧЕТ'!$C:$C,M$1) -> 1 | N34: =COUNTIFS('ЕЖЕДНЕВНЫЙ УЧЕТ'!$J:$J,$A34,'ЕЖЕДНЕВНЫЙ УЧЕТ'!$C:$C,N$1) -> 2 | O34: =COUNTIFS('ЕЖЕДНЕВНЫЙ УЧЕТ'!$J:$J,$A34,'ЕЖЕДНЕВНЫЙ УЧЕТ'!$C:$C,O$1) -> 3 | P34: =COUNTIFS('ЕЖЕДНЕВНЫЙ УЧЕТ'!$J:$J,$A34,'ЕЖЕДНЕВНЫЙ УЧЕТ'!$C:$C,P$1) -> 0 | Q34: =COUNTIFS('ЕЖЕДНЕВНЫЙ УЧЕТ'!$J:$J,$A34,'ЕЖЕДНЕВНЫЙ УЧЕТ'!$C:$C,Q$1) -> 0 | R34: =COUNTIFS('ЕЖЕДНЕВНЫЙ УЧЕТ'!$J:$J,$A34,'ЕЖЕДНЕВНЫЙ УЧЕТ'!$C:$C,R$1) -> 0 | ... AU34: =COUNTIFS('ЕЖЕДНЕВНЫЙ УЧЕТ'!$J:$J,$A34,'ЕЖЕДНЕВНЫЙ УЧЕТ'!$C:$C,AU$1) -> 0
A35: Специалист по охране труда (полевой) | B35: =COUNTIF('ЕЖЕДНЕВНЫЙ УЧЕТ'!J:J,СВОД!A35) -> 160 | C35: =IFERROR(B35/$B$121,"") -> 0.011695906 | E35: Участок ОР | F35: =COUNTIFS('ЕЖЕДНЕВНЫЙ УЧЕТ'!$K:$K,СВОД!$E35,'ЕЖЕДНЕВНЫЙ УЧЕТ'!$Q:$Q,СВОД!F$1) -> 75 | G35: =IFERROR(F35/$F$48,"") -> 0.035494558 | H35: =COUNTIFS('ЕЖЕДНЕВНЫЙ УЧЕТ'!$K:$K,СВОД!$E35,'ЕЖЕДНЕВНЫЙ УЧЕТ'!$Q:$Q,СВОД!H$1) -> 1290 | I35: =IFERROR(H35/$H$48,"") -> 0.11152416 | K35: =COUNTIFS('ЕЖЕДНЕВНЫЙ УЧЕТ'!$J:$J,$A35,'ЕЖЕДНЕВНЫЙ УЧЕТ'!$C:$C,K$1) -> 0 | L35: =COUNTIFS('ЕЖЕДНЕВНЫЙ УЧЕТ'!$J:$J,$A35,'ЕЖЕДНЕВНЫЙ УЧЕТ'!$C:$C,L$1) -> 0 | M35: =COUNTIFS('ЕЖЕДНЕВНЫЙ УЧЕТ'!$J:$J,$A35,'ЕЖЕДНЕВНЫЙ УЧЕТ'!$C:$C,M$1) -> 0 | N35: =COUNTIFS('ЕЖЕДНЕВНЫЙ УЧЕТ'!$J:$J,$A35,'ЕЖЕДНЕВНЫЙ УЧЕТ'!$C:$C,N$1) -> 2 | O35: =COUNTIFS('ЕЖЕДНЕВНЫЙ УЧЕТ'!$J:$J,$A35,'ЕЖЕДНЕВНЫЙ УЧЕТ'!$C:$C,O$1) -> 12 | P35: =COUNTIFS('ЕЖЕДНЕВНЫЙ УЧЕТ'!$J:$J,$A35,'ЕЖЕДНЕВНЫЙ УЧЕТ'!$C:$C,P$1) -> 0 | Q35: =COUNTIFS('ЕЖЕДНЕВНЫЙ УЧЕТ'!$J:$J,$A35,'ЕЖЕДНЕВНЫЙ УЧЕТ'!$C:$C,Q$1) -> 3 | R35: =COUNTIFS('ЕЖЕДНЕВНЫЙ УЧЕТ'!$J:$J,$A35,'ЕЖЕДНЕВНЫЙ УЧЕТ'!$C:$C,R$1) -> 2 | ... AU35: =COUNTIFS('ЕЖЕДНЕВНЫЙ УЧЕТ'!$J:$J,$A35,'ЕЖЕДНЕВНЫЙ УЧЕТ'!$C:$C,AU$1) -> 0
A36: Специалист по здоровью | B36: =COUNTIF('ЕЖЕДНЕВНЫЙ УЧЕТ'!J:J,СВОД!A36) -> 25 | C36: =IFERROR(B36/$B$121,"") -> 0.0018274854 | E36: Участок АКЗ | F36: =COUNTIFS('ЕЖЕДНЕВНЫЙ УЧЕТ'!$K:$K,СВОД!$E36,'ЕЖЕДНЕВНЫЙ УЧЕТ'!$Q:$Q,СВОД!F$1) -> 98 | G36: =IFERROR(F36/$F$48,"") -> 0.046379555 | H36: =COUNTIFS('ЕЖЕДНЕВНЫЙ УЧЕТ'!$K:$K,СВОД!$E36,'ЕЖЕДНЕВНЫЙ УЧЕТ'!$Q:$Q,СВОД!H$1) -> 2012 | I36: =IFERROR(H36/$H$48,"") -> 0.17394311 | K36: =COUNTIFS('ЕЖЕДНЕВНЫЙ УЧЕТ'!$J:$J,$A36,'ЕЖЕДНЕВНЫЙ УЧЕТ'!$C:$C,K$1) -> 0 | L36: =COUNTIFS('ЕЖЕДНЕВНЫЙ УЧЕТ'!$J:$J,$A36,'ЕЖЕДНЕВНЫЙ УЧЕТ'!$C:$C,L$1) -> 0 | M36: =COUNTIFS('ЕЖЕДНЕВНЫЙ УЧЕТ'!$J:$J,$A36,'ЕЖЕДНЕВНЫЙ УЧЕТ'!$C:$C,M$1) -> 0 | N36: =COUNTIFS('ЕЖЕДНЕВНЫЙ УЧЕТ'!$J:$J,$A36,'ЕЖЕДНЕВНЫЙ УЧЕТ'!$C:$C,N$1) -> 1 | O36: =COUNTIFS('ЕЖЕДНЕВНЫЙ УЧЕТ'!$J:$J,$A36,'ЕЖЕДНЕВНЫЙ УЧЕТ'!$C:$C,O$1) -> 3 | P36: =COUNTIFS('ЕЖЕДНЕВНЫЙ УЧЕТ'!$J:$J,$A36,'ЕЖЕДНЕВНЫЙ УЧЕТ'!$C:$C,P$1) -> 0 | Q36: =COUNTIFS('ЕЖЕДНЕВНЫЙ УЧЕТ'!$J:$J,$A36,'ЕЖЕДНЕВНЫЙ УЧЕТ'!$C:$C,Q$1) -> 1 | R36: =COUNTIFS('ЕЖЕДНЕВНЫЙ УЧЕТ'!$J:$J,$A36,'ЕЖЕДНЕВНЫЙ УЧЕТ'!$C:$C,R$1) -> 0 | ... AU36: =COUNTIFS('ЕЖЕДНЕВНЫЙ УЧЕТ'!$J:$J,$A36,'ЕЖЕДНЕВНЫЙ УЧЕТ'!$C:$C,AU$1) -> 0
A37: Начальник отдела по обеспечению безопасности | B37: =COUNTIF('ЕЖЕДНЕВНЫЙ УЧЕТ'!J:J,СВОД!A37) -> 0 | C37: =IFERROR(B37/$B$121,"") -> 0 | E37: Участок ОиВ | F37: =COUNTIFS('ЕЖЕДНЕВНЫЙ УЧЕТ'!$K:$K,СВОД!$E37,'ЕЖЕДНЕВНЫЙ УЧЕТ'!$Q:$Q,СВОД!F$1) -> 19 | G37: =IFERROR(F37/$F$48,"") -> 0.0089919546 | H37: =COUNTIFS('ЕЖЕДНЕВНЫЙ УЧЕТ'!$K:$K,СВОД!$E37,'ЕЖЕДНЕВНЫЙ УЧЕТ'!$Q:$Q,СВОД!H$1) -> 349 | I37: =IFERROR(H37/$H$48,"") -> 0.030172041 | K37: =COUNTIFS('ЕЖЕДНЕВНЫЙ УЧЕТ'!$J:$J,$A37,'ЕЖЕДНЕВНЫЙ УЧЕТ'!$C:$C,K$1) -> 0 | L37: =COUNTIFS('ЕЖЕДНЕВНЫЙ УЧЕТ'!$J:$J,$A37,'ЕЖЕДНЕВНЫЙ УЧЕТ'!$C:$C,L$1) -> 0 | M37: =COUNTIFS('ЕЖЕДНЕВНЫЙ УЧЕТ'!$J:$J,$A37,'ЕЖЕДНЕВНЫЙ УЧЕТ'!$C:$C,M$1) -> 0 | N37: =COUNTIFS('ЕЖЕДНЕВНЫЙ УЧЕТ'!$J:$J,$A37,'ЕЖЕДНЕВНЫЙ УЧЕТ'!$C:$C,N$1) -> 0 | O37: =COUNTIFS('ЕЖЕДНЕВНЫЙ УЧЕТ'!$J:$J,$A37,'ЕЖЕДНЕВНЫЙ УЧЕТ'!$C:$C,O$1) -> 0 | P37: =COUNTIFS('ЕЖЕДНЕВНЫЙ УЧЕТ'!$J:$J,$A37,'ЕЖЕДНЕВНЫЙ УЧЕТ'!$C:$C,P$1) -> 0 | Q37: =COUNTIFS('ЕЖЕДНЕВНЫЙ УЧЕТ'!$J:$J,$A37,'ЕЖЕДНЕВНЫЙ УЧЕТ'!$C:$C,Q$1) -> 0 | R37: =COUNTIFS('ЕЖЕДНЕВНЫЙ УЧЕТ'!$J:$J,$A37,'ЕЖЕДНЕВНЫЙ УЧЕТ'!$C:$C,R$1) -> 0 | ... AU37: =COUNTIFS('ЕЖЕДНЕВНЫЙ УЧЕТ'!$J:$J,$A37,'ЕЖЕДНЕВНЫЙ УЧЕТ'!$C:$C,AU$1) -> 0
A38: Ведущий специалист отдела по обеспечению безопасности | B38: =COUNTIF('ЕЖЕДНЕВНЫЙ УЧЕТ'!J:J,СВОД!A38) -> 4 | C38: =IFERROR(B38/$B$121,"") -> 0.00029239766 | E38: Участок ВиК | F38: =COUNTIFS('ЕЖЕДНЕВНЫЙ УЧЕТ'!$K:$K,СВОД!$E38,'ЕЖЕДНЕВНЫЙ УЧЕТ'!$Q:$Q,СВОД!F$1) -> 8 | G38: =IFERROR(F38/$F$48,"") -> 0.0037860861 | H38: =COUNTIFS('ЕЖЕДНЕВНЫЙ УЧЕТ'!$K:$K,СВОД!$E38,'ЕЖЕДНЕВНЫЙ УЧЕТ'!$Q:$Q,СВОД!H$1) -> 140 | I38: =IFERROR(H38/$H$48,"") -> 0.012103398 | K38: =COUNTIFS('ЕЖЕДНЕВНЫЙ УЧЕТ'!$J:$J,$A38,'ЕЖЕДНЕВНЫЙ УЧЕТ'!$C:$C,K$1) -> 0 | L38: =COUNTIFS('ЕЖЕДНЕВНЫЙ УЧЕТ'!$J:$J,$A38,'ЕЖЕДНЕВНЫЙ УЧЕТ'!$C:$C,L$1) -> 0 | M38: =COUNTIFS('ЕЖЕДНЕВНЫЙ УЧЕТ'!$J:$J,$A38,'ЕЖЕДНЕВНЫЙ УЧЕТ'!$C:$C,M$1) -> 0 | N38: =COUNTIFS('ЕЖЕДНЕВНЫЙ УЧЕТ'!$J:$J,$A38,'ЕЖЕДНЕВНЫЙ УЧЕТ'!$C:$C,N$1) -> 0 | O38: =COUNTIFS('ЕЖЕДНЕВНЫЙ УЧЕТ'!$J:$J,$A38,'ЕЖЕДНЕВНЫЙ УЧЕТ'!$C:$C,O$1) -> 0 | P38: =COUNTIFS('ЕЖЕДНЕВНЫЙ УЧЕТ'!$J:$J,$A38,'ЕЖЕДНЕВНЫЙ УЧЕТ'!$C:$C,P$1) -> 0 | Q38: =COUNTIFS('ЕЖЕДНЕВНЫЙ УЧЕТ'!$J:$J,$A38,'ЕЖЕДНЕВНЫЙ УЧЕТ'!$C:$C,Q$1) -> 0 | R38: =COUNTIFS('ЕЖЕДНЕВНЫЙ УЧЕТ'!$J:$J,$A38,'ЕЖЕДНЕВНЫЙ УЧЕТ'!$C:$C,R$1) -> 0 | ... AU38: =COUNTIFS('ЕЖЕДНЕВНЫЙ УЧЕТ'!$J:$J,$A38,'ЕЖЕДНЕВНЫЙ УЧЕТ'!$C:$C,AU$1) -> 0
A39: Специалист отдела по обеспечению безопасности | B39: =COUNTIF('ЕЖЕДНЕВНЫЙ УЧЕТ'!J:J,СВОД!A39) -> 3 | C39: =IFERROR(B39/$B$121,"") -> 0.00021929825 | E39: Участок ЗР | F39: =COUNTIFS('ЕЖЕДНЕВНЫЙ УЧЕТ'!$K:$K,СВОД!$E39,'ЕЖЕДНЕВНЫЙ УЧЕТ'!$Q:$Q,СВОД!F$1) -> 16 | G39: =IFERROR(F39/$F$48,"") -> 0.0075721723 | H39: =COUNTIFS('ЕЖЕДНЕВНЫЙ УЧЕТ'!$K:$K,СВОД!$E39,'ЕЖЕДНЕВНЫЙ УЧЕТ'!$Q:$Q,СВОД!H$1) -> 382 | I39: =IFERROR(H39/$H$48,"") -> 0.033024985 | K39: =COUNTIFS('ЕЖЕДНЕВНЫЙ УЧЕТ'!$J:$J,$A39,'ЕЖЕДНЕВНЫЙ УЧЕТ'!$C:$C,K$1) -> 0 | L39: =COUNTIFS('ЕЖЕДНЕВНЫЙ УЧЕТ'!$J:$J,$A39,'ЕЖЕДНЕВНЫЙ УЧЕТ'!$C:$C,L$1) -> 0 | M39: =COUNTIFS('ЕЖЕДНЕВНЫЙ УЧЕТ'!$J:$J,$A39,'ЕЖЕДНЕВНЫЙ УЧЕТ'!$C:$C,M$1) -> 0 | N39: =COUNTIFS('ЕЖЕДНЕВНЫЙ УЧЕТ'!$J:$J,$A39,'ЕЖЕДНЕВНЫЙ УЧЕТ'!$C:$C,N$1) -> 0 | O39: =COUNTIFS('ЕЖЕДНЕВНЫЙ УЧЕТ'!$J:$J,$A39,'ЕЖЕДНЕВНЫЙ УЧЕТ'!$C:$C,O$1) -> 0 | P39: =COUNTIFS('ЕЖЕДНЕВНЫЙ УЧЕТ'!$J:$J,$A39,'ЕЖЕДНЕВНЫЙ УЧЕТ'!$C:$C,P$1) -> 0 | Q39: =COUNTIFS('ЕЖЕДНЕВНЫЙ УЧЕТ'!$J:$J,$A39,'ЕЖЕДНЕВНЫЙ УЧЕТ'!$C:$C,Q$1) -> 0 | R39: =COUNTIFS('ЕЖЕДНЕВНЫЙ УЧЕТ'!$J:$J,$A39,'ЕЖЕДНЕВНЫЙ УЧЕТ'!$C:$C,R$1) -> 0 | ... AU39: =COUNTIFS('ЕЖЕДНЕВНЫЙ УЧЕТ'!$J:$J,$A39,'ЕЖЕДНЕВНЫЙ УЧЕТ'!$C:$C,AU$1) -> 0
A40: Начальник ПТО | B40: =COUNTIF('ЕЖЕДНЕВНЫЙ УЧЕТ'!J:J,СВОД!A40) -> 8 | C40: =IFERROR(B40/$B$121,"") -> 0.00058479532 | E40: Участок ТИ | F40: =COUNTIFS('ЕЖЕДНЕВНЫЙ УЧЕТ'!$K:$K,СВОД!$E40,'ЕЖЕДНЕВНЫЙ УЧЕТ'!$Q:$Q,СВОД!F$1) -> 59 | G40: =IFERROR(F40/$F$48,"") -> 0.027922385 | H40: =COUNTIFS('ЕЖЕДНЕВНЫЙ УЧЕТ'!$K:$K,СВОД!$E40,'ЕЖЕДНЕВНЫЙ УЧЕТ'!$Q:$Q,СВОД!H$1) -> 665 | I40: =IFERROR(H40/$H$48,"") -> 0.057491139 | K40: =COUNTIFS('ЕЖЕДНЕВНЫЙ УЧЕТ'!$J:$J,$A40,'ЕЖЕДНЕВНЫЙ УЧЕТ'!$C:$C,K$1) -> 0 | L40: =COUNTIFS('ЕЖЕДНЕВНЫЙ УЧЕТ'!$J:$J,$A40,'ЕЖЕДНЕВНЫЙ УЧЕТ'!$C:$C,L$1) -> 0 | M40: =COUNTIFS('ЕЖЕДНЕВНЫЙ УЧЕТ'!$J:$J,$A40,'ЕЖЕДНЕВНЫЙ УЧЕТ'!$C:$C,M$1) -> 1 | N40: =COUNTIFS('ЕЖЕДНЕВНЫЙ УЧЕТ'!$J:$J,$A40,'ЕЖЕДНЕВНЫЙ УЧЕТ'!$C:$C,N$1) -> 1 | O40: =COUNTIFS('ЕЖЕДНЕВНЫЙ УЧЕТ'!$J:$J,$A40,'ЕЖЕДНЕВНЫЙ УЧЕТ'!$C:$C,O$1) -> 1 | P40: =COUNTIFS('ЕЖЕДНЕВНЫЙ УЧЕТ'!$J:$J,$A40,'ЕЖЕДНЕВНЫЙ УЧЕТ'!$C:$C,P$1) -> 0 | Q40: =COUNTIFS('ЕЖЕДНЕВНЫЙ УЧЕТ'!$J:$J,$A40,'ЕЖЕДНЕВНЫЙ УЧЕТ'!$C:$C,Q$1) -> 0 | R40: =COUNTIFS('ЕЖЕДНЕВНЫЙ УЧЕТ'!$J:$J,$A40,'ЕЖЕДНЕВНЫЙ УЧЕТ'!$C:$C,R$1) -> 0 | ... AU40: =COUNTIFS('ЕЖЕДНЕВНЫЙ УЧЕТ'!$J:$J,$A40,'ЕЖЕДНЕВНЫЙ УЧЕТ'!$C:$C,AU$1) -> 0
...

Sheet Структура рабочих
B5: СТРУКТУРА РАБОЧИХ ООО ВелесстройМонтаж
B6: ='ЕЖЕДНЕВНЫЙ УЧЕТ'!$B$1 -> 46139 | C6: ИТР | E6: Рабочие | G6: ИТОГО
B7: Гражданство | C7: =SUM(C8:C30) -> 2113 | E7: =SUM(E8:E30) -> 11567 | G7: =SUM(G8:G30) -> 13680
B8: АЗЕРБАЙДЖАН | C8: =СВОД!F2 -> 0 | D8: =СВОД!G2 -> 0 | E8: =СВОД!H2 -> 0 | F8: =СВОД!I2 -> 0 | G8: =SUM(C8,E8) -> 0 | H8: =IFERROR(G8/$G$7,"") -> 0
B9: АРМЕНИЯ | C9: =СВОД!F3 -> 1 | D9: =СВОД!G3 -> 0.00047326077 | E9: =СВОД!H3 -> 0 | F9: =СВОД!I3 -> 0 | G9: =SUM(C9,E9) -> 1 | H9: =IFERROR(G9/$G$7,"") -> 7.3099415e-05
B10: БЕЛАРУСЬ | C10: =СВОД!F4 -> 30 | D10: =СВОД!G4 -> 0.014197823 | E10: =СВОД!H4 -> 52 | F10: =СВОД!I4 -> 0.0044955477 | G10: =SUM(C10,E10) -> 82 | H10: =IFERROR(G10/$G$7,"") -> 0.005994152
B11: БОСНИЯ И ГЕРЦЕГОВИНА | C11: =СВОД!F5 -> 17 | D11: =СВОД!G5 -> 0.008045433 | E11: =СВОД!H5 -> 3 | F11: =СВОД!I5 -> 0.00025935852 | G11: =SUM(C11,E11) -> 20 | H11: =IFERROR(G11/$G$7,"") -> 0.0014619883
B12: ГАНА | C12: =СВОД!F6 -> 0 | D12: =СВОД!G6 -> 0 | E12: =СВОД!H6 -> 0 | F12: =СВОД!I6 -> 0 | G12: =SUM(C12,E12) -> 0 | H12: =IFERROR(G12/$G$7,"") -> 0
B13: ИНДИЯ | C13: =СВОД!F7 -> 105 | D13: =СВОД!G7 -> 0.049692381 | E13: =СВОД!H7 -> 1781 | F13: =СВОД!I7 -> 0.15397251 | G13: =SUM(C13,E13) -> 1886 | H13: =IFERROR(G13/$G$7,"") -> 0.1378655
B14: КАЗАХСТАН | C14: =СВОД!F8 -> 256 | D14: =СВОД!G8 -> 0.12115476 | E14: =СВОД!H8 -> 2384 | F14: =СВОД!I8 -> 0.20610357 | G14: =SUM(C14,E14) -> 2640 | H14: =IFERROR(G14/$G$7,"") -> 0.19298246
B15: КИРГИЗИЯ | C15: =СВОД!F9 -> 144 | D15: =СВОД!G9 -> 0.06814955 | E15: =СВОД!H9 -> 1803 | F15: =СВОД!I9 -> 0.15587447 | G15: =SUM(C15,E15) -> 1947 | H15: =IFERROR(G15/$G$7,"") -> 0.14232456
B16: КИТАЙ | C16: =СВОД!F10 -> 9 | D16: =СВОД!G10 -> 0.0042593469 | E16: =СВОД!H10 -> 72 | F16: =СВОД!I10 -> 0.0062246045 | G16: =SUM(C16,E16) -> 81 | H16: =IFERROR(G16/$G$7,"") -> 0.0059210526
B17: МОЛДОВА, РЕСПУБЛИКА | C17: =СВОД!F11 -> 0 | D17: =СВОД!G11 -> 0 | E17: =СВОД!H11 -> 0 | F17: =СВОД!I11 -> 0 | G17: =SUM(C17,E17) -> 0 | H17: =IFERROR(G17/$G$7,"") -> 0
B18: ПАКИСТАН | C18: =СВОД!F12 -> 1 | D18: =СВОД!G12 -> 0.00047326077 | E18: =СВОД!H12 -> 0 | F18: =СВОД!I12 -> 0 | G18: =SUM(C18,E18) -> 1 | H18: =IFERROR(G18/$G$7,"") -> 7.3099415e-05
B19: РОССИЯ | C19: =СВОД!F13 -> 1116 | D19: =СВОД!G13 -> 0.52815902 | E19: =СВОД!H13 -> 531 | F19: =СВОД!I13 -> 0.045906458 | G19: =SUM(C19,E19) -> 1647 | H19: =IFERROR(G19/$G$7,"") -> 0.12039474
... B30: ЧЕРНОГОРИЯ | C30: =СВОД!F24 -> 1 | D30: =СВОД!G24 -> 0.00047326077 | E30: =СВОД!H24 -> 0 | F30: =СВОД!I24 -> 0 | G30: =SUM(C30,E30) -> 1 | H30: =IFERROR(G30/$G$7,"") -> 7.3099415e-05
B31: Участок/Отдел | C31: =SUM(C32:C46) -> 2113 | E31: =SUM(E32:E46) -> 11567 | G31: =SUM(G32:G46) -> 13680
B32: Административно-управленческий персонал | C32: =+СВОД!F30 -> 1233 | D32: =+СВОД!G30 -> 0.58353053 | E32: =+СВОД!H30 -> 0 | F32: =+СВОД!I30 -> 0 | G32: =SUM(C32,E32) -> 1233 | H32: =IFERROR(G32/$G$31,"") -> 0.090131579
B33: Вспомагательное произв. и непром. персонал | C33: =+СВОД!F31 -> 116 | D33: =+СВОД!G31 -> 0.054898249 | E33: =+СВОД!H31 -> 0 | F33: =+СВОД!I31 -> 0 | G33: =SUM(C33,E33) -> 116 | H33: =IFERROR(G33/$G$31,"") -> 0.0084795322
B34: Участок монолитно-бетонных работ | C34: =+СВОД!F34 -> 309 | D34: =+СВОД!G34 -> 0.14623758 | E34: =+СВОД!H34 -> 4121 | F34: =+СВОД!I34 -> 0.35627215 | G34: =SUM(C34,E34) -> 4430 | H34: =IFERROR(G34/$G$31,"") -> 0.32383041
B35: Участок отделочных работ | C35: =+СВОД!F35 -> 75 | D35: =+СВОД!G35 -> 0.035494558 | E35: =+СВОД!H35 -> 1290 | F35: =+СВОД!I35 -> 0.11152416 | G35: =SUM(C35,E35) -> 1365 | H35: =IFERROR(G35/$G$31,"") -> 0.099780702
